Workbook
Name ArbeidsgiverAvgift: Innstillinger!$D$8
Name Feriepenger: Innstillinger!$D$10
Name Firmanavn: Innstillinger!$D$4
Name Pensjon: Innstillinger!$D$12
Name StartÅr: Innstillinger!$D$6
Name Utfyllingsmodus: Innstillinger!$H$14

Sheet Info
B1: Info
B2: =Firmanavn -> Eksempelbedriften AS
C4: Kom I gang med arket
C6: Først bør du registrere firmanavn, åre og flere opplysninger på siden "Innstillinger". Her er det også mulighet til å slå på "Utfyllingsmodusen". Når du krysser av her, vil alle celler som du kan fylle ut tydelig merkes.
C8: Sammendrag historisk
C10: Lønn
C12: I første kolonne kan du legge inn ansattenavn. I den andre kolonne legger du inn stillingsprosenten (den brukes dog bare som informasjon - ikke til beregning). Deretter registrerer du lønn for alle månedene. Kostnader som AGA, feriepenger og pensjon beregnes automatisk
C14: Budsjett
C16: På budsjettet legger du inn detaljene som inntekter, driftskostnader og finanskostnader. På driftskostnadene er det en dele foreslag til vanlige kontoer. Du kan gjerne endre disse etter eget behov eller legge til nye kontoer.
C18: Styrerapport
C20: De fleste verdiene hentes automatisk. Det er kun informasjon om aksjonærinnskud som må legges inn manuellt. På bunnen av arket finner du også en grafisk fremmstilling av resultatene. I tillegg kan du velge (ved hjelp av sjekkboksene) hvilke nøkkeltal du ønsker å vise i diagrammet.
C42: Ansvarsfraskrivelse
C44: Dette verktøyet ble satt etter best kunnskap og evne. Dog leveres arket "som den er" og uten garantier. Det kan ikke utelukkes at verktøyet inneholder tekniske, matematiske, logiske eller andre type feil. Du bruker derfor arket på eget ansvar.
C46: Videreutvikling av verktøyet
C48: Du er også velkommen til å foreta endringer i verktøyet selv. Arkene er låst, men har ikke passord. Du får dermed bare klikke på "Se gjennom" > "Beskytt" > "Opphev arkbeskyttelse". Det er ikke anbefalt å fjerne beskyttelse så lenge du ikke ønsker å endre arkstrukturen. Du kan legge inn verdier selv om arket er beskyttet. Beskyttelsen hinder at relevante deler av arket blir ødelagt.

Sheet Innstillinger
B1: Innstillinger
B2: =Firmanavn -> Eksempelbedriften AS
B4: Firmanavn | D4: Eksempelbedriften AS
B6: Start år | D6: 2020
B8: Arbeidsgiver avgift | D8: 0.141
B10: Feriepenger | D10: 0.12
B12: Pensjon | D12: 0.02
H14: TRUE

Sheet Sammendrag historisk 
B1: Historisk utvikling
B2: =Firmanavn -> Eksempelbedriften AS
D4: =StartÅr -> 2020
C5: i NOK tusen | D5: Budsjett
C7: Inntekter | D7: =Budsjett!P13 -> 3240
C8: Sum inntekter | D8: =SUM(D7) -> 3240
C10: Varekostnader | D10: =Budsjett!P28 -> 486
C11: Sum varekostnader | D11: =SUM(D10) -> 486
C13: Lønn | D13: =Budsjett!P49 -> 1173.204
C14: Sum lønnskostnader | D14: =SUM(D13) -> 1173.204
C16: Avskrivninger | D16: =Budsjett!P52 -> 36
C17: Andre driftskostnader | D17: =(Budsjett!P53+Budsjett!P54+Budsjett!P55+Budsjett!P56+Budsjett!P57+Budsjett!P58+Budsjett!P59+Budsjett!P60+Budsjett!P61+Budsjett!P62+Budsjett!P63+Budsjett!P64+Budsjett!P65+Budsjett!P66+Budsjett!P67+Budsjett!P78+Budsjett!P79+Budsjett!P80+Budsjett!P81+Budsjett!P82+Budsjett!P86+Budsjett!P87+Budsjett!P88+Budsjett!P89+Budsjett!P90+Budsjett!P91+Budsjett!P92+Budsjett!P93+Budsjett!P94+Budsjett!P95+Budsjett!P96+Budsjett!P97+Budsjett!P98+Budsjett!P99+Budsjett!P100+Budsjett!P101) -> 469
C18: Sum andre driftskostnader | D18: =SUM(D16:D17) -> 505
C20: Driftsresultat | D20: =D8-D11-D14-D18 -> 1075.796
C22: Finansinntekter | D22: =(Budsjett!P113+Budsjett!P114+Budsjett!P115) -> 17
C23: Finanskostnader | D23: =Budsjett!P116 -> 37
C24: Sum nto finans | D24: =D22-D23 -> -20
C26: Resultat før skatt | D26: =D20+D24 -> 1055.796

Sheet Styrerapport
B1: ="Prognose og likviditet for " & StartÅr -> Prognose og likviditet for 2020
B2: =Firmanavn -> Eksempelbedriften AS
T3: DIAGRAMTITEL
C4: Kontantstrøm | T4: ="Utvikling i kontantbeholdning per måned " & StartÅr+1 -> Utvikling i kontantbeholdning per måned 2021
C5: NOK i tusen | D5: Januar | E5: Februar | F5: Mars | G5: April | H5: Mai | I5: Juni | J5: Juli | K5: August | L5: September | M5: Oktober | N5: November | O5: Desember | P5: Total | T5: ="Utvikling per måned " & StartÅr -> Utvikling per måned 2020
C6: Inntekter | D6: =Budsjett!D13 -> 270 | E6: =Budsjett!E13 -> 270 | F6: =Budsjett!F13 -> 270 | G6: =Budsjett!G13 -> 270 | H6: =Budsjett!H13 -> 270 | I6: =Budsjett!I13 -> 270 | J6: =Budsjett!J13 -> 270 | K6: =Budsjett!K13 -> 270 | ... O6: =Budsjett!O13 -> 270 | P6: =SUM(D6:O6) -> 3240
C7: Utgifter | D7: =Budsjett!D28+Budsjett!D49+Budsjett!D83+Budsjett!D110+Budsjett!D117 -> 173.267 | E7: =Budsjett!E28+Budsjett!E49+Budsjett!E83+Budsjett!E110+Budsjett!E117 -> 175.267 | F7: =Budsjett!F28+Budsjett!F49+Budsjett!F83+Budsjett!F110+Budsjett!F117 -> 187.267 | G7: =Budsjett!G28+Budsjett!G49+Budsjett!G83+Budsjett!G110+Budsjett!G117 -> 188.267 | H7: =Budsjett!H28+Budsjett!H49+Budsjett!H83+Budsjett!H110+Budsjett!H117 -> 175.267 | I7: =Budsjett!I28+Budsjett!I49+Budsjett!I83+Budsjett!I110+Budsjett!I117 -> 177.267 | J7: =Budsjett!J28+Budsjett!J49+Budsjett!J83+Budsjett!J110+Budsjett!J117 -> 181.267 | K7: =Budsjett!K28+Budsjett!K49+Budsjett!K83+Budsjett!K110+Budsjett!K117 -> 175.267 | ... O7: =Budsjett!O28+Budsjett!O49+Budsjett!O83+Budsjett!O110+Budsjett!O117 -> 178.267 | P7: =SUM(D7:O7) -> 2144.204
C8: Kontantstrøm nto | D8: =D6-D7 -> 96.733 | E8: =E6-E7 -> 94.733 | F8: =F6-F7 -> 82.733 | G8: =G6-G7 -> 81.733 | H8: =H6-H7 -> 94.733 | I8: =I6-I7 -> 92.733 | J8: =J6-J7 -> 88.733 | K8: =K6-K7 -> 94.733 | ... P8: =P6-P7 -> 1095.796
C10: Inngående balanse
C11: =Firmanavn -> Eksempelbedriften AS | P11: =SUM(D11:O11) -> 0
C12: Kunder | D12: 150 | P12: =SUM(D12:O12) -> 150
C13: Leverandører | D13: 75 | P13: =SUM(D13:O13) -> 75
C14: Kontantstrøm i perioden | D14: =D11+D12-D13 -> 75 | E14: =E11+E12-E13 -> 0 | F14: =F11+F12-F13 -> 0 | G14: =G11+G12-G13 -> 0 | H14: =H11+H12-H13 -> 0 | I14: =I11+I12-I13 -> 0 | J14: =J11+J12-J13 -> 0 | K14: =K11+K12-K13 -> 0 | ... P14: =P11+P12-P13 -> 75
C16: Kontantbeholdning IB | D16: 890 | E16: =D17 -> 1061.733 | F16: =E17 -> 1156.466 | G16: =F17 -> 1239.199 | H16: =G17 -> 1320.932 | I16: =H17 -> 1415.665 | J16: =I17 -> 1508.398 | K16: =J17 -> 1597.131 | L16: =K17 -> 1691.864 | ... P16: =O17 -> 2060.796
C17: Kontantbeholdning UB | D17: =D8+D14+D16 -> 1061.733 | E17: =E8+E14+E16 -> 1156.466 | F17: =F8+F14+F16 -> 1239.199 | G17: =G8+G14+G16 -> 1320.932 | H17: =H8+H14+H16 -> 1415.665 | I17: =I8+I14+I16 -> 1508.398 | J17: =J8+J14+J16 -> 1597.131 | K17: =K8+K14+K16 -> 1691.864 | ... O17: =O8+O14+O16 -> 2060.796 | P17: =P16 -> 2060.796
C25: Regnskap/prognose
C26: NOK i tusen | D26: Januar | E26: Februar | F26: Mars | G26: April | H26: Mai | I26: Juni | J26: Juli | K26: August | L26: September | M26: Oktober | N26: November | O26: Desember | P26: Total
C27: Driftsinntekter | D27: =Budsjett!D13 -> 270 | E27: =Budsjett!E13 -> 270 | F27: =Budsjett!F13 -> 270 | G27: =Budsjett!G13 -> 270 | H27: =Budsjett!H13 -> 270 | I27: =Budsjett!I13 -> 270 | J27: =Budsjett!J13 -> 270 | K27: =Budsjett!K13 -> 270 | ... O27: =Budsjett!O13 -> 270 | P27: =SUM(D27:O27) -> 3240
C28: Varekost | D28: =Budsjett!D28 -> 40.5 | E28: =Budsjett!E28 -> 40.5 | F28: =Budsjett!F28 -> 40.5 | G28: =Budsjett!G28 -> 40.5 | H28: =Budsjett!H28 -> 40.5 | I28: =Budsjett!I28 -> 40.5 | J28: =Budsjett!J28 -> 40.5 | K28: =Budsjett!K28 -> 40.5 | ... O28: =Budsjett!O28 -> 40.5 | P28: =SUM(D28:O28) -> 486
C29: DBI | D29: =D27-D28 -> 229.5 | E29: =E27-E28 -> 229.5 | F29: =F27-F28 -> 229.5 | G29: =G27-G28 -> 229.5 | H29: =H27-H28 -> 229.5 | I29: =I27-I28 -> 229.5 | J29: =J27-J28 -> 229.5 | K29: =K27-K28 -> 229.5 | ... O29: =O27-O28 -> 229.5 | P29: =SUM(D29:O29) -> 2754
C30: DG% | D30: =IFERROR(D29/D27,0) -> 0.85 | E30: =IFERROR(E29/E27,0) -> 0.85 | F30: =IFERROR(F29/F27,0) -> 0.85 | G30: =IFERROR(G29/G27,0) -> 0.85 | H30: =IFERROR(H29/H27,0) -> 0.85 | I30: =IFERROR(I29/I27,0) -> 0.85 | J30: =IFERROR(J29/J27,0) -> 0.85 | K30: =IFERROR(K29/K27,0) -> 0.85 | ... P30: =IFERROR(P29/P27,0) -> 0.85
C31: Personalkost | D31: =Budsjett!D49 -> 97.767 | E31: =Budsjett!E49 -> 97.767 | F31: =Budsjett!F49 -> 97.767 | G31: =Budsjett!G49 -> 97.767 | H31: =Budsjett!H49 -> 97.767 | I31: =Budsjett!I49 -> 97.767 | J31: =Budsjett!J49 -> 97.767 | K31: =Budsjett!K49 -> 97.767 | ... O31: =Budsjett!O49 -> 97.767 | P31: =SUM(D31:O31) -> 1173.204
C32: Andre driftskost | D32: =Budsjett!D83+Budsjett!D110 -> 35 | E32: =Budsjett!E83+Budsjett!E110 -> 37 | F32: =Budsjett!F83+Budsjett!F110 -> 50 | G32: =Budsjett!G83+Budsjett!G110 -> 50 | H32: =Budsjett!H83+Budsjett!H110 -> 37 | I32: =Budsjett!I83+Budsjett!I110 -> 40 | J32: =Budsjett!J83+Budsjett!J110 -> 43 | K32: =Budsjett!K83+Budsjett!K110 -> 37 | ... O32: =Budsjett!O83+Budsjett!O110 -> 40 | P32: =SUM(D32:O32) -> 505
C33: Avskrivninger | D33: =Budsjett!D52 -> 3 | E33: =Budsjett!E52 -> 3 | F33: =Budsjett!F52 -> 3 | G33: =Budsjett!G52 -> 3 | H33: =Budsjett!H52 -> 3 | I33: =Budsjett!I52 -> 3 | J33: =Budsjett!J52 -> 3 | K33: =Budsjett!K52 -> 3 | ... O33: =Budsjett!O52 -> 3 | P33: =SUM(D33:O33) -> 36
C34: Driftsresultat | D34: =D27-D28-D31-D32 -> 96.733 | E34: =E27-E28-E31-E32 -> 94.733 | F34: =F27-F28-F31-F32 -> 81.733 | G34: =G27-G28-G31-G32 -> 81.733 | H34: =H27-H28-H31-H32 -> 94.733 | I34: =I27-I28-I31-I32 -> 91.733 | J34: =J27-J28-J31-J32 -> 88.733 | K34: =K27-K28-K31-K32 -> 94.733 | ... O34: =O27-O28-O31-O32 -> 91.733 | P34: =SUM(D34:O34) -> 1075.796
C35: Netto finans | D35: =Budsjett!D117 -> 0 | E35: =Budsjett!E117 -> 0 | F35: =Budsjett!F117 -> -1 | G35: =Budsjett!G117 -> 0 | H35: =Budsjett!H117 -> 0 | I35: =Budsjett!I117 -> -1 | J35: =Budsjett!J117 -> 0 | K35: =Budsjett!K117 -> 0 | ... O35: =Budsjett!O117 -> 0 | P35: =SUM(D35:O35) -> -20
C36: Resultat før skatt | D36: =D34-D35 -> 96.733 | E36: =E34+E35 -> 94.733 | F36: =F34+F35 -> 80.733 | G36: =G34+G35 -> 81.733 | H36: =H34+H35 -> 94.733 | I36: =I34+I35 -> 90.733 | J36: =J34+J35 -> 88.733 | K36: =K34+K35 -> 94.733 | L36: =L34+L35 -> 78.733 | ... P36: =P34+P35 -> 1055.796
C73: =C27 -> Driftsinntekter | D73: =IF($A73,D27,NA()) -> #N/A | E73: =IF($A73,E27,NA()) -> #N/A | F73: =IF($A73,F27,NA()) -> #N/A | G73: =IF($A73,G27,NA()) -> #N/A | H73: =IF($A73,H27,NA()) -> #N/A | I73: =IF($A73,I27,NA()) -> #N/A | J73: =IF($A73,J27,NA()) -> #N/A | K73: =IF($A73,K27,NA()) -> #N/A | ... O73: =IF($A73,O27,NA()) -> #N/A
C74: =C28 -> Varekost | D74: =IF($A74,D28,NA()) -> #N/A | E74: =IF($A74,E28,NA()) -> #N/A | F74: =IF($A74,F28,NA()) -> #N/A | G74: =IF($A74,G28,NA()) -> #N/A | H74: =IF($A74,H28,NA()) -> #N/A | I74: =IF($A74,I28,NA()) -> #N/A | J74: =IF($A74,J28,NA()) -> #N/A | K74: =IF($A74,K28,NA()) -> #N/A | ... O74: =IF($A74,O28,NA()) -> #N/A
C75: =C29 -> DBI | D75: =IF($A75,D29,NA()) -> #N/A | E75: =IF($A75,E29,NA()) -> #N/A | F75: =IF($A75,F29,NA()) -> #N/A | G75: =IF($A75,G29,NA()) -> #N/A | H75: =IF($A75,H29,NA()) -> #N/A | I75: =IF($A75,I29,NA()) -> #N/A | J75: =IF($A75,J29,NA()) -> #N/A | K75: =IF($A75,K29,NA()) -> #N/A | ... O75: =IF($A75,O29,NA()) -> #N/A
C76: =C30 -> DG% | D76: =IF($A76,D30,NA()) -> #N/A | E76: =IF($A76,E30,NA()) -> #N/A | F76: =IF($A76,F30,NA()) -> #N/A | G76: =IF($A76,G30,NA()) -> #N/A | H76: =IF($A76,H30,NA()) -> #N/A | I76: =IF($A76,I30,NA()) -> #N/A | J76: =IF($A76,J30,NA()) -> #N/A | K76: =IF($A76,K30,NA()) -> #N/A | ... O76: =IF($A76,O30,NA()) -> #N/A
C77: =C31 -> Personalkost | D77: =IF($A77,D31,NA()) -> #N/A | E77: =IF($A77,E31,NA()) -> #N/A | F77: =IF($A77,F31,NA()) -> #N/A | G77: =IF($A77,G31,NA()) -> #N/A | H77: =IF($A77,H31,NA()) -> #N/A | I77: =IF($A77,I31,NA()) -> #N/A | J77: =IF($A77,J31,NA()) -> #N/A | K77: =IF($A77,K31,NA()) -> #N/A | ... O77: =IF($A77,O31,NA()) -> #N/A
A78: FALSE | C78: =C32 -> Andre driftskost | D78: =IF($A78,D32,NA()) -> #N/A | E78: =IF($A78,E32,NA()) -> #N/A | F78: =IF($A78,F32,NA()) -> #N/A | G78: =IF($A78,G32,NA()) -> #N/A | H78: =IF($A78,H32,NA()) -> #N/A | I78: =IF($A78,I32,NA()) -> #N/A | J78: =IF($A78,J32,NA()) -> #N/A | K78: =IF($A78,K32,NA()) -> #N/A | ... O78: =IF($A78,O32,NA()) -> #N/A
C79: =C33 -> Avskrivninger | D79: =IF($A79,D33,NA()) -> #N/A | E79: =IF($A79,E33,NA()) -> #N/A | F79: =IF($A79,F33,NA()) -> #N/A | G79: =IF($A79,G33,NA()) -> #N/A | H79: =IF($A79,H33,NA()) -> #N/A | I79: =IF($A79,I33,NA()) -> #N/A | J79: =IF($A79,J33,NA()) -> #N/A | K79: =IF($A79,K33,NA()) -> #N/A | ... O79: =IF($A79,O33,NA()) -> #N/A
C80: =C34 -> Driftsresultat | D80: =IF($A80,D34,NA()) -> #N/A | E80: =IF($A80,E34,NA()) -> #N/A | F80: =IF($A80,F34,NA()) -> #N/A | G80: =IF($A80,G34,NA()) -> #N/A | H80: =IF($A80,H34,NA()) -> #N/A | I80: =IF($A80,I34,NA()) -> #N/A | J80: =IF($A80,J34,NA()) -> #N/A | K80: =IF($A80,K34,NA()) -> #N/A | ... O80: =IF($A80,O34,NA()) -> #N/A
C81: =C35 -> Netto finans | D81: =IF($A81,D35,NA()) -> #N/A | E81: =IF($A81,E35,NA()) -> #N/A | F81: =IF($A81,F35,NA()) -> #N/A | G81: =IF($A81,G35,NA()) -> #N/A | H81: =IF($A81,H35,NA()) -> #N/A | I81: =IF($A81,I35,NA()) -> #N/A | J81: =IF($A81,J35,NA()) -> #N/A | K81: =IF($A81,K35,NA()) -> #N/A | ... O81: =IF($A81,O35,NA()) -> #N/A
C82: =C36 -> Resultat før skatt | D82: =IF($A82,D36,NA()) -> #N/A | E82: =IF($A82,E36,NA()) -> #N/A | F82: =IF($A82,F36,NA()) -> #N/A | G82: =IF($A82,G36,NA()) -> #N/A | H82: =IF($A82,H36,NA()) -> #N/A | I82: =IF($A82,I36,NA()) -> #N/A | J82: =IF($A82,J36,NA()) -> #N/A | K82: =IF($A82,K36,NA()) -> #N/A | ... O82: =IF($A82,O36,NA()) -> #N/A

Sheet Budsjett
B1: ="Budsjett " & StartÅr+1 -> Budsjett 2021
B2: =Firmanavn -> Eksempelbedriften AS
C4: NOK i tusen | D4: Januar | E4: Februar | F4: Mars | G4: April | H4: Mai | I4: Juni | J4: Juli | K4: August | L4: September | M4: Oktober | N4: November | O4: Desember | P4: Totalt
C6: Salg
C7: 3000 - Inntekt 1 | D7: 150 | E7: 150 | F7: 150 | G7: 150 | H7: 150 | I7: 150 | J7: 150 | K7: 150 | L7: 150 | M7: 150 | N7: 150 | O7: 150 | P7: =SUM(D7:O7) -> 1800
C8: 3001 - Inntekt 2 | D8: 75 | E8: 75 | F8: 75 | G8: 75 | H8: 75 | I8: 75 | J8: 75 | K8: 75 | L8: 75 | M8: 75 | N8: 75 | O8: 75 | P8: =SUM(D8:O8) -> 900
C9: 3005 - Inntekt 3 | D9: 30 | E9: 30 | F9: 30 | G9: 30 | H9: 30 | I9: 30 | J9: 30 | K9: 30 | L9: 30 | M9: 30 | N9: 30 | O9: 30 | P9: =SUM(D9:O9) -> 360
C10: 3009 - Inntekt 4 | D10: 15 | E10: 15 | F10: 15 | G10: 15 | H10: 15 | I10: 15 | J10: 15 | K10: 15 | L10: 15 | M10: 15 | N10: 15 | O10: 15 | P10: =SUM(D10:O10) -> 180
P11: =SUM(D11:O11) -> 0
P12: =SUM(D12:O12) -> 0
C13: Sum Salg | D13: =SUM(D7:D12) -> 270 | E13: =SUM(E7:E12) -> 270 | F13: =SUM(F7:F12) -> 270 | G13: =SUM(G7:G12) -> 270 | H13: =SUM(H7:H12) -> 270 | I13: =SUM(I7:I12) -> 270 | J13: =SUM(J7:J12) -> 270 | K13: =SUM(K7:K12) -> 270 | ... P13: =SUM(P7:P12) -> 3240
C15: Varekjøp
C16: 4000 - Varekjøp 1 | D16: 15 | E16: 15 | F16: 15 | G16: 15 | H16: 15 | I16: 15 | J16: 15 | K16: 15 | L16: 15 | M16: 15 | N16: 15 | O16: 15 | P16: =SUM(D16:O16) -> 180
C17: 4001 - Varekjøp 2 | D17: 10 | E17: 10 | F17: 10 | G17: 10 | H17: 10 | I17: 10 | J17: 10 | K17: 10 | L17: 10 | M17: 10 | N17: 10 | O17: 10 | P17: =SUM(D17:O17) -> 120
C18: 4005 - Varekjøp 3 | D18: 7.5 | E18: 7.5 | F18: 7.5 | G18: 7.5 | H18: 7.5 | I18: 7.5 | J18: 7.5 | K18: 7.5 | L18: 7.5 | M18: 7.5 | N18: 7.5 | O18: 7.5 | P18: =SUM(D18:O18) -> 90
C19: 4009 - Varekjøp 4 | D19: 8 | E19: 8 | F19: 8 | G19: 8 | H19: 8 | I19: 8 | J19: 8 | K19: 8 | L19: 8 | M19: 8 | N19: 8 | O19: 8 | P19: =SUM(D19:O19) -> 96
P20: =SUM(D20:O20) -> 0
P21: =SUM(D21:O21) -> 0
P22: =SUM(D22:O22) -> 0
P23: =SUM(D23:O23) -> 0
P24: =SUM(D24:O24) -> 0
P25: =SUM(D25:O25) -> 0
P26: =SUM(D26:O26) -> 0
P27: =SUM(D27:O27) -> 0
C28: Sum Varekjøp | D28: =SUM(D16:D27) -> 40.5 | E28: =SUM(E16:E27) -> 40.5 | F28: =SUM(F16:F27) -> 40.5 | G28: =SUM(G16:G27) -> 40.5 | H28: =SUM(H16:H27) -> 40.5 | I28: =SUM(I16:I27) -> 40.5 | J28: =SUM(J16:J27) -> 40.5 | K28: =SUM(K16:K27) -> 40.5 | ... P28: =SUM(P16:P27) -> 486
C30: DB | D30: =D13-D28 -> 229.5 | E30: =E13-E28 -> 229.5 | F30: =F13-F28 -> 229.5 | G30: =G13-G28 -> 229.5 | H30: =H13-H28 -> 229.5 | I30: =I13-I28 -> 229.5 | J30: =J13-J28 -> 229.5 | K30: =K13-K28 -> 229.5 | ... P30: =P13-P28 -> 2754
C31: DG% | D31: =IFERROR(D30/D13,0) -> 0.85 | E31: =IFERROR(E30/E13,0) -> 0.85 | F31: =IFERROR(F30/F13,0) -> 0.85 | G31: =IFERROR(G30/G13,0) -> 0.85 | H31: =IFERROR(H30/H13,0) -> 0.85 | I31: =IFERROR(I30/I13,0) -> 0.85 | J31: =IFERROR(J30/J13,0) -> 0.85 | K31: =IFERROR(K30/K13,0) -> 0.85 | ... P31: =IFERROR(P30/P13,0) -> 0.85
C33: Lønn
C34: 5000 - Lønn til ansatte | D34: ='Lønn '!E13 -> 75 | E34: ='Lønn '!F13 -> 75 | F34: ='Lønn '!G13 -> 75 | G34: ='Lønn '!H13 -> 75 | H34: ='Lønn '!I13 -> 75 | I34: ='Lønn '!J13 -> 75 | J34: ='Lønn '!K13 -> 75 | K34: ='Lønn '!L13 -> 75 | ... O34: ='Lønn '!P13 -> 75 | P34: =SUM(D34:O34) -> 900
C35: 5010 - Sykelønn (arb.giv.per) | P35: =SUM(D35:O35) -> 0
C36: 5040 - Provisjon | P36: =SUM(D36:O36) -> 0
C37: 5180 - Feriepenger beregnet | D37: ='Lønn '!E15 -> 9 | E37: ='Lønn '!F15 -> 9 | F37: ='Lønn '!G15 -> 9 | G37: ='Lønn '!H15 -> 9 | H37: ='Lønn '!I15 -> 9 | I37: ='Lønn '!J15 -> 9 | J37: ='Lønn '!K15 -> 9 | K37: ='Lønn '!L15 -> 9 | ... O37: ='Lønn '!P15 -> 9 | P37: =SUM(D37:O37) -> 108
C38: 5182 - Arb.avg. påløpne feriepenger | D38: ='Lønn '!E16 -> 1.269 | E38: ='Lønn '!F16 -> 1.269 | F38: ='Lønn '!G16 -> 1.269 | G38: ='Lønn '!H16 -> 1.269 | H38: ='Lønn '!I16 -> 1.269 | I38: ='Lønn '!J16 -> 1.269 | J38: ='Lønn '!K16 -> 1.269 | K38: ='Lønn '!L16 -> 1.269 | ... O38: ='Lønn '!P16 -> 1.269 | P38: =SUM(D38:O38) -> 15.228
C39: 5210 - Elektronisk kommunikasjon | P39: =SUM(D39:O39) -> 0
C40: 5290 - Motkonto elektronisk kommunikasjon | P40: =SUM(D40:O40) -> 0
C41: 5400 - Arbeidsgiveravgift | D41: ='Lønn '!E14 -> 10.7865 | E41: ='Lønn '!F14 -> 10.7865 | F41: ='Lønn '!G14 -> 10.7865 | G41: ='Lønn '!H14 -> 10.7865 | H41: ='Lønn '!I14 -> 10.7865 | I41: ='Lønn '!J14 -> 10.7865 | J41: ='Lønn '!K14 -> 10.7865 | K41: ='Lønn '!L14 -> 10.7865 | ... O41: ='Lønn '!P14 -> 10.7865 | P41: =SUM(D41:O41) -> 129.438
C42: 5400 - Arbeidsgiveravgift OTP | D42: ='Lønn '!E18 -> 0.2115 | E42: ='Lønn '!F18 -> 0.2115 | F42: ='Lønn '!G18 -> 0.2115 | G42: ='Lønn '!H18 -> 0.2115 | H42: ='Lønn '!I18 -> 0.2115 | I42: ='Lønn '!J18 -> 0.2115 | J42: ='Lønn '!K18 -> 0.2115 | K42: ='Lønn '!L18 -> 0.2115 | ... O42: ='Lønn '!P18 -> 0.2115 | P42: =SUM(D42:O42) -> 2.538
C43: 5910 - Kantine | P43: =SUM(D43:O43) -> 0
C44: 5920 - Yrkesskadeforsikring | P44: =SUM(D44:O44) -> 0
C45: 5945 - Innskuddspensjon | P45: =SUM(D45:O45) -> 0
...

Sheet Lønn 
B1: Lønn
B2: =Firmanavn -> Eksempelbedriften AS
C4: Ansatt | D4: Stillingstr.% | E4: Jan | F4: Feb | G4: Mar | H4: Apr | I4: Mai | J4: Jun | K4: Jul | L4: Aug | M4: Sep | N4: Okt | O4: Nov | P4: Des | Q4: Totalt
C5: Ola Nordmann | D5: 0.7 | E5: 25 | F5: 25 | G5: 25 | H5: 25 | I5: 25 | J5: 25 | K5: 25 | L5: 25 | M5: 25 | N5: 25 | O5: 25 | P5: 25 | Q5: =SUM(E5:P5) -> 300
C6: Peder Ås | D6: 1 | E6: 50 | F6: 50 | G6: 50 | H6: 50 | I6: 50 | J6: 50 | K6: 50 | L6: 50 | M6: 50 | N6: 50 | O6: 50 | P6: 50 | Q6: =SUM(E6:P6) -> 600
Q7: =SUM(E7:P7) -> 0
Q8: =SUM(E8:P8) -> 0
Q9: =SUM(E9:P9) -> 0
Q10: =SUM(E10:P10) -> 0
Q11: =SUM(E11:P11) -> 0
Q12: =SUM(E12:P12) -> 0
C13: Sum lønn | E13: =SUM(E5:E11) -> 75 | F13: =SUM(F5:F11) -> 75 | G13: =SUM(G5:G11) -> 75 | H13: =SUM(H5:H11) -> 75 | I13: =SUM(I5:I11) -> 75 | J13: =SUM(J5:J11) -> 75 | K13: =SUM(K5:K11) -> 75 | L13: =SUM(L5:L11) -> 75 | ... Q13: =SUM(Q5:Q11) -> 900
C14: Arb. giver avg | E14: =(E13+E17)*ArbeidsgiverAvgift -> 10.7865 | F14: =(F13+F17)*ArbeidsgiverAvgift -> 10.7865 | G14: =(G13+G17)*ArbeidsgiverAvgift -> 10.7865 | H14: =(H13+H17)*ArbeidsgiverAvgift -> 10.7865 | I14: =(I13+I17)*ArbeidsgiverAvgift -> 10.7865 | J14: =(J13+J17)*ArbeidsgiverAvgift -> 10.7865 | K14: =(K13+K17)*ArbeidsgiverAvgift -> 10.7865 | L14: =(L13+L17)*ArbeidsgiverAvgift -> 10.7865 | ... Q14: =(Q13+Q17)*ArbeidsgiverAvgift -> 129.438
C15: Feriepenger | E15: =E13*Feriepenger -> 9 | F15: =F13*Feriepenger -> 9 | G15: =G13*Feriepenger -> 9 | H15: =H13*Feriepenger -> 9 | I15: =I13*Feriepenger -> 9 | J15: =J13*Feriepenger -> 9 | K15: =K13*Feriepenger -> 9 | L15: =L13*Feriepenger -> 9 | ... Q15: =Q13*Feriepenger -> 108
C16: Arb. giver avg påløpt feriepenger | E16: =E15*ArbeidsgiverAvgift -> 1.269 | F16: =F15*ArbeidsgiverAvgift -> 1.269 | G16: =G15*ArbeidsgiverAvgift -> 1.269 | H16: =H15*ArbeidsgiverAvgift -> 1.269 | I16: =I15*ArbeidsgiverAvgift -> 1.269 | J16: =J15*ArbeidsgiverAvgift -> 1.269 | K16: =K15*ArbeidsgiverAvgift -> 1.269 | L16: =L15*ArbeidsgiverAvgift -> 1.269 | ... Q16: =Q15*ArbeidsgiverAvgift -> 15.228
C17: Pensjon | E17: =E13*Pensjon -> 1.5 | F17: =F13*Pensjon -> 1.5 | G17: =G13*Pensjon -> 1.5 | H17: =H13*Pensjon -> 1.5 | I17: =I13*Pensjon -> 1.5 | J17: =J13*Pensjon -> 1.5 | K17: =K13*Pensjon -> 1.5 | L17: =L13*Pensjon -> 1.5 | ... Q17: =Q13*Pensjon -> 18
C18: Arb. giver avg pensjon | E18: =ArbeidsgiverAvgift*E17 -> 0.2115 | F18: =ArbeidsgiverAvgift*F17 -> 0.2115 | G18: =ArbeidsgiverAvgift*G17 -> 0.2115 | H18: =ArbeidsgiverAvgift*H17 -> 0.2115 | I18: =ArbeidsgiverAvgift*I17 -> 0.2115 | J18: =ArbeidsgiverAvgift*J17 -> 0.2115 | K18: =ArbeidsgiverAvgift*K17 -> 0.2115 | L18: =ArbeidsgiverAvgift*L17 -> 0.2115 | ... P18: =ArbeidsgiverAvgift*P17 -> 0.2115 | Q18: =Q14*Pensjon -> 2.58876
C19: Sum | E19: =SUM(E13:E18) -> 97.767 | F19: =SUM(F13:F18) -> 97.767 | G19: =SUM(G13:G18) -> 97.767 | H19: =SUM(H13:H18) -> 97.767 | I19: =SUM(I13:I18) -> 97.767 | J19: =SUM(J13:J18) -> 97.767 | K19: =SUM(K13:K18) -> 97.767 | L19: =SUM(L13:L18) -> 97.767 | ... Q19: =SUM(Q13:Q18) -> 1173.2548
