Workbook

Sheet Lønn
A1: Lønnsoversikt - 20XX
A3: NAVN | B3: TIMELØNN | C3: PR.MND | D3: LØNN U.FP | E3: FP 12 % | F3: TOTALT
A4: Daglig leder | B4: =C4/(37.5*4.333) -> 307.71598 | C4: 50000 | D4: =SUM(C4*11) -> 550000 | E4: =SUM(D4*12%) -> 66000 | F4: =SUM(D4+E4) -> 616000
A5: Adm.sjef | B5: =C5/(37.5*4.333) -> 169.24379 | C5: 27500 | D5: =SUM(C5*11) -> 302500 | E5: =SUM(D5*12%) -> 36300 | F5: =SUM(D5+E5) -> 338800
A6: TOTALT | C6: =SUM(C4:C5) -> 77500 | D6: =SUM(D4:D5) -> 852500 | E6: =SUM(E4:E5) -> 102300 | F6: =SUM(F4:F5) -> 954800
A9: Periodiserte lønnskostnader - 20XX
A10: Periodisering av lønnskostnader
A11: NAVN | B11: Jan | C11: Feb | D11: Mar | E11: Apr | F11: Mai | G11: Jun | H11: Jul | I11: Aug | J11: Sep | K11: Okt | L11: Nov | M11: Des | N11: Totalt
A12: =A4 -> Daglig leder | B12: =$C4 -> 50000 | C12: =$C4 -> 50000 | D12: =$C4 -> 50000 | E12: =$C4 -> 50000 | F12: =$C4 -> 50000 | G12: =$C4 -> 50000 | H12: =$H4 -> 0 | I12: =$C4 -> 50000 | J12: =$C4 -> 50000 | K12: =$C4 -> 50000 | L12: =$C4 -> 50000 | M12: =$C4 -> 50000 | N12: =SUM(B12:M12) -> 550000
A13: Adm.sjef | B13: =$C5 -> 27500 | C13: =$C5 -> 27500 | D13: =$C5 -> 27500 | E13: =$C5 -> 27500 | F13: =$C5 -> 27500 | G13: =$C5 -> 27500 | H13: =$H5 -> 0 | I13: =$C5 -> 27500 | J13: =$C5 -> 27500 | K13: =$C5 -> 27500 | L13: =$C5 -> 27500 | M13: =$C5 -> 27500 | N13: =SUM(B13:M13) -> 302500
A14: TOTALT | B14: =SUM(B12:B13) -> 77500 | C14: =SUM(C12:C13) -> 77500 | D14: =SUM(D12:D13) -> 77500 | E14: =SUM(E12:E13) -> 77500 | F14: =SUM(F12:F13) -> 77500 | G14: =SUM(G12:G13) -> 77500 | H14: =SUM(H12:H13) -> 0 | I14: =SUM(I12:I13) -> 77500 | ... M14: =SUM(M12:M13) -> 77500 | N14: =SUM(B14:M14) -> 852500
A16: Feriepenger | B16: =(B14)*10.2% -> 7905 | C16: =(C14)*10.2% -> 7905 | D16: =(D14)*10.2% -> 7905 | E16: =(E14)*10.2% -> 7905 | F16: =(F14)*10.2% -> 7905 | G16: =(G14)*10.2% -> 7905 | H16: =(H14)*10.2% -> 0 | I16: =(I14)*10.2% -> 7905 | ... M16: =(M14)*10.2% -> 7905 | N16: =SUM(B16:M16) -> 86955
A17: Arbeidsgiveravgift | B17: =(B14+B16)*14.1% -> 12042.105 | C17: =(C14+C16)*14.1% -> 12042.105 | D17: =(D14+D16)*14.1% -> 12042.105 | E17: =(E14+E16)*14.1% -> 12042.105 | F17: =(F14+F16)*14.1% -> 12042.105 | G17: =(G14+G16)*14.1% -> 12042.105 | H17: =(H14+H16)*14.1% -> 0 | I17: =(I14+I16)*14.1% -> 12042.105 | ... M17: =(M14+M16)*14.1% -> 12042.105 | N17: =SUM(B17:M17) -> 132463.15
A18: Arb.avg.feriepenger | B18: =B16*12% -> 948.6 | C18: =C16*12% -> 948.6 | D18: =D16*12% -> 948.6 | E18: =E16*12% -> 948.6 | F18: =F16*12% -> 948.6 | G18: =G16*12% -> 948.6 | H18: =H16*12% -> 0 | I18: =I16*12% -> 948.6 | ... M18: =M16*12% -> 948.6 | N18: =SUM(B18:M18) -> 10434.6
A19: Sum personalkostnader | B19: =SUM(B14+B16+B17+B18) -> 98395.705 | C19: =SUM(C14+C16+C17+C18) -> 98395.705 | D19: =SUM(D14+D16+D17+D18) -> 98395.705 | E19: =SUM(E14+E16+E17+E18) -> 98395.705 | F19: =SUM(F14+F16+F17+F18) -> 98395.705 | G19: =SUM(G14+G16+G17+G18) -> 98395.705 | H19: =SUM(H14+H16+H17+H18) -> 0 | I19: =SUM(I14+I16+I17+I18) -> 98395.705 | ... N19: =SUM(N14+N16+N17+N18) -> 1082352.8

Sheet Kostnadsspes.
B1: Jan. | C1: Feb | D1: Mar | E1: Apr | F1: Mai | G1: Jun | H1: Jul | I1: Aug | J1: Sep | K1: Okt | L1: Nov | M1: Des | N1: Totalt
A3: Salgsinntekter
A4: Salgsinntekter avg.pliktig. | B4: 500000 | C4: 500000 | D4: 500000 | E4: 2500000 | F4: 1500000 | G4: 500000 | H4: 0 | I4: 500000 | J4: 1000000 | K4: 2000000 | L4: 600000 | M4: 200000 | N4: =SUM(B4:M4) -> 10300000
A5: Salgsinntekter avg. Fritt | B5: 200000 | C5: 200000 | D5: 400000 | E5: 200000 | F5: 200000 | G5: 200000 | H5: 100000 | I5: 500000 | J5: 800000 | K5: 800000 | L5: 200000 | M5: 200000 | N5: =SUM(B5:M5) -> 4000000
A6: Husleie inntekter | B6: =B5*40% -> 80000 | C6: =C5*40% -> 80000 | D6: =D5*40% -> 160000 | E6: =E5*40% -> 80000 | F6: =F5*40% -> 80000 | G6: =G5*40% -> 80000 | H6: =H5*40% -> 40000 | I6: =I5*40% -> 200000 | ... M6: =M5*40% -> 80000 | N6: =SUM(B6:M6) -> 1600000
A7: Andre driftsinntekter | B7: 1500 | C7: 1500 | D7: 1500 | E7: 1500 | F7: 1500 | G7: 1500 | H7: 1500 | I7: 1500 | J7: 1500 | K7: 1500 | L7: 1500 | M7: 1500 | N7: =SUM(B7:M7) -> 18000
A8: Sum salgsinntekter | B8: =SUM(B3:B7) -> 781500 | C8: =SUM(C3:C7) -> 781500 | D8: =SUM(D3:D7) -> 1061500 | E8: =SUM(E3:E7) -> 2781500 | F8: =SUM(F3:F7) -> 1781500 | G8: =SUM(G3:G7) -> 781500 | H8: =SUM(H3:H7) -> 141500 | I8: =SUM(I3:I7) -> 1201500 | ... N8: =SUM(N3:N7) -> 15918000
A11: Varekostnader
A12: Varekjøp avg.pliktig | B12: 0 | C12: 0 | D12: 0 | E12: 0 | F12: 0 | G12: 0 | H12: 0 | N12: =SUM(B12:M12) -> 0
A13: Varekjøp avg.fritt | B13: =(B5+B6)*80%*-1 -> -224000 | C13: =(C5+C6)*80%*-1 -> -224000 | D13: =(D5+D6)*80%*-1 -> -448000 | E13: =(E5+E6)*80%*-1 -> -224000 | F13: =(F5+F6)*80%*-1 -> -224000 | G13: =(G5+G6)*80%*-1 -> -224000 | H13: =(H5+H6)*80%*-1 -> -112000 | I13: =(I5+I6)*80%*-1 -> -560000 | ... M13: =(M5+M6)*80%*-1 -> -224000 | N13: =SUM(B13:M13) -> -4480000
A14: Diverse varekjøp utland | B14: =B4*80%*-1 -> -400000 | C14: =C4*80%*-1 -> -400000 | D14: =D4*80%*-1 -> -400000 | E14: =E4*80%*-1 -> -2000000 | F14: =F4*80%*-1 -> -1200000 | G14: =G4*80%*-1 -> -400000 | H14: =H4*80%*-1 -> 0 | I14: =I4*80%*-1 -> -400000 | ... M14: =M4*80%*-1 -> -160000 | N14: =SUM(B14:M14) -> -8240000
A15: Sum varekostnader | B15: =SUM(B12:B14) -> -624000 | C15: =SUM(C12:C14) -> -624000 | D15: =SUM(D12:D14) -> -848000 | E15: =SUM(E12:E14) -> -2224000 | F15: =SUM(F12:F14) -> -1424000 | G15: =SUM(G12:G14) -> -624000 | H15: =SUM(H12:H14) -> -112000 | I15: =SUM(I12:I14) -> -960000 | ... N15: =SUM(N12:N14) -> -12720000
A17: DBI | B17: =B8+B15 -> 157500 | C17: =C8+C15 -> 157500 | D17: =D8+D15 -> 213500 | E17: =E8+E15 -> 557500 | F17: =F8+F15 -> 357500 | G17: =G8+G15 -> 157500 | H17: =H8+H15 -> 29500 | I17: =I8+I15 -> 241500 | ... N17: =N8+N15 -> 3198000
A18: DB% | B18: =B17/B8 -> 0.20153551 | C18: =C17/C8 -> 0.20153551 | D18: =D17/D8 -> 0.20113048 | E18: =E17/E8 -> 0.20043142 | F18: =F17/F8 -> 0.20067359 | G18: =G17/G8 -> 0.20153551 | H18: =H17/H8 -> 0.20848057 | I18: =I17/I8 -> 0.20099875 | ... N18: =N17/N8 -> 0.20090464
A21: Lønnskostnader
A22: Lønn til ansatte | B22: =Lønn!B14*-1 -> -77500 | C22: =Lønn!C14*-1 -> -77500 | D22: =Lønn!D14*-1 -> -77500 | E22: =Lønn!E14*-1 -> -77500 | F22: =Lønn!F14*-1 -> -77500 | G22: =Lønn!G14*-1 -> -77500 | H22: =Lønn!H14*-1 -> 0 | I22: =Lønn!I14*-1 -> -77500 | ... M22: =Lønn!M14*-1 -> -77500 | N22: =SUM(B22:M22) -> -852500
A23: Bilgodtgjørelse avgiftspliktig | N23: =SUM(B23:M23) -> 0
A24: Fri bil | B24: 4500 | C24: 4500 | D24: 4500 | E24: 4500 | F24: 4500 | G24: 4500 | H24: 4500 | I24: 4500 | J24: 4500 | K24: 4500 | L24: 4500 | M24: 4500 | N24: =SUM(B24:M24) -> 54000
A25: Motkonto fri bil | B25: -4500 | C25: -4500 | D25: -4500 | E25: -4500 | F25: -4500 | G25: -4500 | H25: -4500 | I25: -4500 | J25: -4500 | K25: -4500 | L25: -4500 | M25: -4500 | N25: =SUM(B25:M25) -> -54000
A26: Mat ved overtidsarbeid | N26: =SUM(B26:M26) -> 0
A27: Feriepenger 12% | B27: =12%*B22 -> -9300 | C27: =12%*C22 -> -9300 | D27: =12%*D22 -> -9300 | E27: =12%*E22 -> -9300 | F27: =12%*F22 -> -9300 | G27: =12%*G22 -> -9300 | H27: =12%*H22 -> 0 | I27: =12%*I22 -> -9300 | ... M27: =12%*M22 -> -9300 | N27: =SUM(B27:M27) -> -102300
A28: Sykepenger | N28: =SUM(B28:M28) -> 0
A29: Arbeidsgiveravgift | B29: =14.1%*(B22+B25) -> -11562 | C29: =14.1%*(C22+C25) -> -11562 | D29: =14.1%*(D22+D25) -> -11562 | E29: =14.1%*(E22+E25) -> -11562 | F29: =14.1%*(F22+F25) -> -11562 | G29: =14.1%*(G22+G25) -> -11562 | H29: =14.1%*(H22+H25) -> -634.5 | I29: =14.1%*(I22+I25) -> -11562 | ... M29: =14.1%*(M22+M25) -> -11562 | N29: =SUM(B29:M29) -> -127816.5
A30: Arb.g.avg.avs.feriep. | B30: =14.1%*B27 -> -1311.3 | C30: =14.1%*C27 -> -1311.3 | D30: =14.1%*D27 -> -1311.3 | E30: =14.1%*E27 -> -1311.3 | F30: =14.1%*F27 -> -1311.3 | G30: =14.1%*G27 -> -1311.3 | H30: =14.1%*H27 -> 0 | I30: =14.1%*I27 -> -1311.3 | ... M30: =14.1%*M27 -> -1311.3 | N30: =SUM(B30:M30) -> -14424.3
A31: Forsikringer | B31: -1500 | C31: -1500 | D31: -1500 | E31: -1500 | F31: -1500 | G31: -1500 | H31: -1500 | I31: -1500 | J31: -1500 | K31: -1500 | L31: -1500 | M31: -1500 | N31: =SUM(B31:M31) -> -18000
A32: Bompenger | B32: -500 | C32: -500 | D32: -500 | E32: -500 | F32: -500 | G32: -500 | H32: -500 | I32: -500 | J32: -500 | K32: -500 | L32: -500 | M32: -500 | N32: =SUM(B32:M32) -> -6000
A33: Trekkpliktig bilgodtgjørelse | N33: =SUM(B33:M33) -> 0
A34: Godtgjørelse til styre | G34: 0 | M34: 0 | N34: =SUM(B34:M34) -> 0
A35: Yrkesskadeforsikring | N35: =SUM(B35:M35) -> 0
A36: Pensjonsforsikring | D36: -5000 | G36: -5000 | J36: -5000 | M36: -5000 | N36: =SUM(B36:M36) -> -20000
A37: Sosiale kostnader | B37: -2500 | C37: -2500 | D37: -2500 | E37: -2500 | F37: -2500 | G37: -2500 | H37: -2500 | I37: -2500 | J37: -2500 | K37: -2500 | L37: -2500 | M37: -35000 | N37: =SUM(B37:M37) -> -62500
A38: Sum lønnskostnad | B38: =SUM(B22:B37) -> -104173.3 | C38: =SUM(C22:C37) -> -104173.3 | D38: =SUM(D22:D37) -> -109173.3 | E38: =SUM(E22:E37) -> -104173.3 | F38: =SUM(F22:F37) -> -104173.3 | G38: =SUM(G22:G37) -> -109173.3 | H38: =SUM(H22:H37) -> -5134.5 | I38: =SUM(I22:I37) -> -104173.3 | ... N38: =SUM(N22:N37) -> -1203540.8
A41: Andre driftskostnader
A42: Avskr. tr.sp.midler/maskiner/inv. | B42: -2000 | C42: -2000 | D42: -2000 | E42: -2000 | F42: -2000 | G42: -2000 | H42: -2000 | I42: -2000 | J42: -2000 | K42: -2000 | L42: -2000 | M42: -2000 | N42: =SUM(B42:M42) -> -24000
A43: Leie lokaler | B43: =-16006*0.5 -> -8003 | C43: =-16006*0.5 -> -8003 | D43: =-16006*0.5 -> -8003 | E43: =-16006*0.5 -> -8003 | F43: =-16006*0.5 -> -8003 | G43: =-16006*0.5 -> -8003 | H43: =-16006*0.5 -> -8003 | I43: =-16006*0.5 -> -8003 | ... M43: =-16006*0.5 -> -8003 | N43: =SUM(B43:M43) -> -96036
A44: Felleskostnader | B44: =-2500*0.5 -> -1250 | C44: =-2500*0.5 -> -1250 | D44: =-2500*0.5 -> -1250 | E44: =-2500*0.5 -> -1250 | F44: =-2500*0.5 -> -1250 | G44: =-2500*0.5 -> -1250 | H44: =-2500*0.5 -> -1250 | I44: =-2500*0.5 -> -1250 | ... M44: =-2500*0.5 -> -1250 | N44: =SUM(B44:M44) -> -15000
A45: Renhold | B45: =-1200*0.5 -> -600 | C45: =-1200*0.5 -> -600 | D45: =-1200*0.5 -> -600 | E45: =-1200*0.5 -> -600 | F45: =-1200*0.5 -> -600 | G45: =-1200*0.5 -> -600 | H45: =-1200*0.5 -> -600 | I45: =-1200*0.5 -> -600 | ... M45: =-1200*0.5 -> -600 | N45: =SUM(B45:M45) -> -7200
A46: Leie transportmidler | B46: -4500 | C46: -4500 | D46: -4500 | E46: -4500 | F46: -4500 | G46: -4500 | H46: -4500 | I46: -4500 | J46: -4500 | K46: -4500 | L46: -4500 | M46: -4500 | N46: =SUM(B46:M46) -> -54000
A47: Honorar revisjon | C47: -5000 | J47: -15000 | M47: -5000 | N47: =SUM(B47:M47) -> -25000
A48: Honorar regnskap | B48: -9000 | C48: -9000 | D48: -9000 | E48: -9000 | F48: -9000 | G48: -9000 | H48: -9000 | I48: -9000 | J48: -9000 | K48: -9000 | L48: -9000 | M48: -9000 | N48: =SUM(B48:M48) -> -108000
...

Sheet Res.
C1: Jan. | D1: Feb | E1: Mar | F1: Apr | G1: Mai | H1: Jun | I1: Jul | J1: Aug | K1: Sep | L1: Okt | M1: Nov | N1: Des | O1: Tot.
A4: Salgsinntekter | C4: =Kostnadsspes.!B8 -> 781500 | D4: =Kostnadsspes.!C8 -> 781500 | E4: =Kostnadsspes.!D8 -> 1061500 | F4: =Kostnadsspes.!E8 -> 2781500 | G4: =Kostnadsspes.!F8 -> 1781500 | H4: =Kostnadsspes.!G8 -> 781500 | I4: =Kostnadsspes.!H8 -> 141500 | J4: =Kostnadsspes.!I8 -> 1201500 | ... O4: =Kostnadsspes.!N8 -> 15918000
B5: Sum driftsinntekter | C5: =SUM(C4:C4) -> 781500 | D5: =SUM(D4:D4) -> 781500 | E5: =SUM(E4:E4) -> 1061500 | F5: =SUM(F4:F4) -> 2781500 | G5: =SUM(G4:G4) -> 1781500 | H5: =SUM(H4:H4) -> 781500 | I5: =SUM(I4:I4) -> 141500 | J5: =SUM(J4:J4) -> 1201500 | ... O5: =SUM(O4:O4) -> 15918000
A8: Varekostnader | C8: =SUM(Kostnadsspes.!B15) -> -624000 | D8: =SUM(Kostnadsspes.!C15) -> -624000 | E8: =SUM(Kostnadsspes.!D15) -> -848000 | F8: =SUM(Kostnadsspes.!E15) -> -2224000 | G8: =SUM(Kostnadsspes.!F15) -> -1424000 | H8: =SUM(Kostnadsspes.!G15) -> -624000 | I8: =SUM(Kostnadsspes.!H15) -> -112000 | J8: =SUM(Kostnadsspes.!I15) -> -960000 | ... O8: =SUM(Kostnadsspes.!N15) -> -12720000
B9: Sum varekjøp | C9: =SUM(C8:C8) -> -624000 | D9: =SUM(D8:D8) -> -624000 | E9: =SUM(E8:E8) -> -848000 | F9: =SUM(F8:F8) -> -2224000 | G9: =SUM(G8:G8) -> -1424000 | H9: =SUM(H8:H8) -> -624000 | I9: =SUM(I8:I8) -> -112000 | J9: =SUM(J8:J8) -> -960000 | ... O9: =SUM(O8:O8) -> -12720000
I10: =F10-G10 -> 0
B11: DB I | C11: =(C5+C9) -> 157500 | D11: =(D5+D9) -> 157500 | E11: =(E5+E9) -> 213500 | F11: =(F5+F9) -> 557500 | G11: =(G5+G9) -> 357500 | H11: =(H5+H9) -> 157500 | I11: =(I5+I9) -> 29500 | J11: =(J5+J9) -> 241500 | ... O11: =(O5+O9) -> 3198000
B12: DG % | C12: =C11/C5*100 -> 20.153551 | D12: =D11/D5*100 -> 20.153551 | E12: =E11/E5*100 -> 20.113048 | F12: =F11/F5*100 -> 20.043142 | G12: =G11/G5*100 -> 20.067359 | H12: =H11/H5*100 -> 20.153551 | I12: =I11/I5*100 -> 20.848057 | J12: =J11/J5*100 -> 20.099875 | ... O12: =O11/O5*100 -> 20.090464
I13: =F13-G13 -> 0
A14: Lønnskostnader | C14: =SUM(Kostnadsspes.!B38) -> -104173.3 | D14: =SUM(Kostnadsspes.!C38) -> -104173.3 | E14: =SUM(Kostnadsspes.!D38) -> -109173.3 | F14: =SUM(Kostnadsspes.!E38) -> -104173.3 | G14: =SUM(Kostnadsspes.!F38) -> -104173.3 | H14: =SUM(Kostnadsspes.!G38) -> -109173.3 | I14: =SUM(Kostnadsspes.!H38) -> -5134.5 | J14: =SUM(Kostnadsspes.!I38) -> -104173.3 | ... O14: =SUM(Kostnadsspes.!N38) -> -1203540.8
B15: Sum lønnskostnader | C15: =SUM(C14) -> -104173.3 | D15: =SUM(D14) -> -104173.3 | E15: =SUM(E14) -> -109173.3 | F15: =SUM(F14) -> -104173.3 | G15: =SUM(G14) -> -104173.3 | H15: =SUM(H14) -> -109173.3 | I15: =SUM(I14) -> -5134.5 | J15: =SUM(J14) -> -104173.3 | ... O15: =SUM(O14) -> -1203540.8
I16: =F16-G16 -> 0
B17: DB II | C17: =C11+C15 -> 53326.7 | D17: =D11+D15 -> 53326.7 | E17: =E11+E15 -> 104326.7 | F17: =F11+F15 -> 453326.7 | G17: =G11+G15 -> 253326.7 | H17: =H11+H15 -> 48326.7 | I17: =I11+I15 -> 24365.5 | J17: =J11+J15 -> 137326.7 | ... O17: =O11+O15 -> 1994459.2
I18: =F18-G18 -> 0
A19: Andre driftskostnader | C19: =SUM(Kostnadsspes.!B43:B71) -> -65203 | D19: =SUM(Kostnadsspes.!C43:C71) -> -70203 | E19: =SUM(Kostnadsspes.!D43:D71) -> -65203 | F19: =SUM(Kostnadsspes.!E43:E71) -> -65203 | G19: =SUM(Kostnadsspes.!F43:F71) -> -65203 | H19: =SUM(Kostnadsspes.!G43:G71) -> -65203 | I19: =SUM(Kostnadsspes.!H43:H71) -> -65203 | J19: =SUM(Kostnadsspes.!I43:I71) -> -65203 | ... O19: =SUM(Kostnadsspes.!N43:N71) -> -857436
A20: Avskrivninger | C20: =SUM(Kostnadsspes.!B42:B42) -> -2000 | D20: =SUM(Kostnadsspes.!C42:C42) -> -2000 | E20: =SUM(Kostnadsspes.!D42:D42) -> -2000 | F20: =SUM(Kostnadsspes.!E42:E42) -> -2000 | G20: =SUM(Kostnadsspes.!F42:F42) -> -2000 | H20: =SUM(Kostnadsspes.!G42:G42) -> -2000 | I20: =SUM(Kostnadsspes.!H42:H42) -> -2000 | J20: =SUM(Kostnadsspes.!I42:I42) -> -2000 | ... O20: =SUM(Kostnadsspes.!N42:N42) -> -24000
B21: Sum driftskostnader | C21: =SUM(C19:C20) -> -67203 | D21: =SUM(D19:D20) -> -72203 | E21: =SUM(E19:E20) -> -67203 | F21: =SUM(F19:F20) -> -67203 | G21: =SUM(G19:G20) -> -67203 | H21: =SUM(H19:H20) -> -67203 | I21: =SUM(I19:I20) -> -67203 | J21: =SUM(J19:J20) -> -67203 | ... O21: =SUM(O19:O20) -> -881436
I22: =F22-G22 -> 0
B23: Driftsresultat | C23: =(C11+C15+C21) -> -13876.3 | D23: =(D11+D15+D21) -> -18876.3 | E23: =(E11+E15+E21) -> 37123.7 | F23: =(F11+F15+F21) -> 386123.7 | G23: =(G11+G15+G21) -> 186123.7 | H23: =(H11+H15+H21) -> -18876.3 | I23: =(I11+I15+I21) -> -42837.5 | J23: =(J11+J15+J21) -> 70123.7 | ... O23: =(O11+O15+O21) -> 1113023.2
I24: =F24-G24 -> 0
A25: Finansinntekter | C25: =SUM(Kostnadsspes.!B76:B77) -> 2400 | D25: =SUM(Kostnadsspes.!C76:C77) -> 2400 | E25: =SUM(Kostnadsspes.!D76:D77) -> 2400 | F25: =SUM(Kostnadsspes.!E76:E77) -> 2400 | G25: =SUM(Kostnadsspes.!F76:F77) -> 2400 | H25: =SUM(Kostnadsspes.!G76:G77) -> 2400 | I25: =SUM(Kostnadsspes.!H76:H77) -> 2400 | J25: =SUM(Kostnadsspes.!I76:I77) -> 2400 | ... O25: =SUM(Kostnadsspes.!N76:N77) -> 28800
A26: Finanskostnader | C26: =SUM(Kostnadsspes.!B78:B80) -> -4300 | D26: =SUM(Kostnadsspes.!C78:C80) -> -4300 | E26: =SUM(Kostnadsspes.!D78:D80) -> -4300 | F26: =SUM(Kostnadsspes.!E78:E80) -> -4300 | G26: =SUM(Kostnadsspes.!F78:F80) -> -4300 | H26: =SUM(Kostnadsspes.!G78:G80) -> -4300 | I26: =SUM(Kostnadsspes.!H78:H80) -> -4300 | J26: =SUM(Kostnadsspes.!I78:I80) -> -4300 | ... O26: =SUM(Kostnadsspes.!N78:N80) -> -51600
B27: Netto finansposter | C27: =SUM(C25:C26) -> -1900 | D27: =SUM(D25:D26) -> -1900 | E27: =SUM(E25:E26) -> -1900 | F27: =SUM(F25:F26) -> -1900 | G27: =SUM(G25:G26) -> -1900 | H27: =SUM(H25:H26) -> -1900 | I27: =SUM(I25:I26) -> -1900 | J27: =SUM(J25:J26) -> -1900 | ... O27: =SUM(O25:O26) -> -22800
A30: Resultat før skattekostnad | C30: =C23+C27 -> -15776.3 | D30: =D23+D27 -> -20776.3 | E30: =E23+E27 -> 35223.7 | F30: =F23+F27 -> 384223.7 | G30: =G23+G27 -> 184223.7 | H30: =H23+H27 -> -20776.3 | I30: =I23+I27 -> -44737.5 | J30: =J23+J27 -> 68223.7 | ... O30: =O23+O27 -> 1090223.2
