Workbook
Name Firmanavn: Innstillinger!$D$4
Name Merverdiavgift: Innstillinger!$D$8
Name StartÅr: Innstillinger!$D$6
Name Utfyllingsmodus: Innstillinger!$H$13

Sheet Info
B1: Info
B2: =Firmanavn -> 0
C4: Kom I gang med arket
C6: Først bør du registrere firmanavn, åre og flere opplysninger på siden "Innstillinger". Her er det også mulighet til å slå på "Utfyllingsmodusen". Når du krysser av her, vil alle celler som du kan fylle ut tydelig merkes.
C8: Regnskap
C10: Alt utfylling skjer på arket "regnskap". Her fyller du ut en standard kontoplan. Deretter skjer beregning av nøkkeltallene på arket "Nøkkeltal".
C12: Grafer
C14: Alle nøkkeltal som beregnes i arket "Nøkkeltal" kan fremstilles I grafisk form. Dette skjer på arket "Grafer". Her har du tre grupper med grafer, "lønnsomhet", "likviditet" og "lønnsomhet". For de fleste grafene er det mulig å velge hviken dataserie du ønsker å se på. Her er det bare å klikke på en av opsjonsknappene.
C16: Ansvarsfraskrivelse
C18: Dette verktøyet ble satt etter best kunnskap og evne. Dog leveres arket "som den er" og uten garantier. Det kan ikke utelukkes at verktøyet inneholder tekniske, matematiske, logiske eller andre type feil. Du bruker derfor arket på eget ansvar.
C20: Videreutvikling av verktøyet
C22: Arkene er låst, men har ikke passord. Du får dermed bare klikke på "Se gjennom" > "Beskytt" > "Opphev arkbeskyttelse". Det er ikke anbefalt å fjerne beskyttelse så lenge du ikke ønsker å endre arkstrukturen. Du kan legge inn verdier selv om arket er beskyttet. Beskyttelsen hinder at relevante deler av arket blir ødelagt.

Sheet Innstillinger
B1: Innstillinger
B2: =Firmanavn -> 0
B4: Firmanavn
B6: Start år
B8: Merverdiavgift
B10: Utfyllingsmodus
H13: TRUE

Sheet Regnskap
B1: Årsregnskap
B2: =Firmanavn -> 0
C4: Resultatregnskap i NOK tusen | D4: =E4+1 -> 7 | E4: =F4+1 -> 6 | F4: =G4+1 -> 5 | G4: =H4+1 -> 4 | H4: =I4+1 -> 3 | I4: =J4+1 -> 2 | J4: =K4+1 -> 1 | K4: =StartÅr -> 0
C5: Inntekter
C6: Sum salgsinntekter
C7: Annen driftsinntekt | D7: 0 | E7: 0 | F7: 0 | G7: 0 | H7: 0 | I7: 0 | J7: 0 | K7: 0
C8: Sum driftsinntekter | D8: =SUM(D6:D7) -> 0 | E8: =SUM(E6:E7) -> 0 | F8: =SUM(F6:F7) -> 0 | G8: =SUM(G6:G7) -> 0 | H8: =SUM(H6:H7) -> 0 | I8: =SUM(I6:I7) -> 0 | J8: =SUM(J6:J7) -> 0 | K8: =SUM(K6:K7) -> 0
C9: Driftskostnader
C10: Varekostnad | D10: =D6*0.48 -> 0 | E10: =E6*0.48 -> 0 | F10: =F6*0.48 -> 0 | G10: =G6*0.48 -> 0 | H10: =H6*0.48 -> 0 | I10: =I6*0.48 -> 0 | J10: =J6*0.48 -> 0 | K10: =K6*0.48 -> 0
C11: Beholdningsendringer | D11: 0 | E11: 0 | F11: 0 | G11: 0 | H11: 0 | I11: 0 | J11: 0 | K11: 0
C12: Lønnskostnader
C13: Ordinære avskrivninger
C14: Nedskrivning
C15: Andre driftskostnader
C16: Sum driftskostnader | D16: =SUM(D10:D15) -> 0 | E16: =SUM(E10:E15) -> 0 | F16: =SUM(F10:F15) -> 0 | G16: =SUM(G10:G15) -> 0 | H16: =SUM(H10:H15) -> 0 | I16: =SUM(I10:I15) -> 0 | J16: =SUM(J10:J15) -> 0 | K16: =SUM(K10:K15) -> 0
C17: Driftsresultat | D17: =D8-D16 -> 0 | E17: =E8-E16 -> 0 | F17: =F8-F16 -> 0 | G17: =G8-G16 -> 0 | H17: =H8-H16 -> 0 | I17: =I8-I16 -> 0 | J17: =J8-J16 -> 0 | K17: =K8-K16 -> 0
C19: Finans
C20: Renteinntekt
C21: Annen finansinntekt | D21: 0 | E21: 0 | F21: 0 | G21: 0 | H21: 0 | I21: 0 | J21: 0 | K21: 0
C22: Sum finansinntekter | D22: =SUM(D20:D21) -> 0 | E22: =SUM(E20:E21) -> 0 | F22: =SUM(F20:F21) -> 0 | G22: =SUM(G20:G21) -> 0 | H22: =SUM(H20:H21) -> 0 | I22: =SUM(I20:I21) -> 0 | J22: =SUM(J20:J21) -> 0 | K22: =SUM(K20:K21) -> 0
C23: Rentekostnader
C24: Andre finanskostnader | D24: 0 | E24: 0 | F24: 0 | G24: 0 | H24: 0 | I24: 0 | J24: 0 | K24: 0
C25: Sum finanskostnader | D25: =SUM(D23:D24) -> 0 | E25: =SUM(E23:E24) -> 0 | F25: =SUM(F23:F24) -> 0 | G25: =SUM(G23:G24) -> 0 | H25: =SUM(H23:H24) -> 0 | I25: =SUM(I23:I24) -> 0 | J25: =SUM(J23:J24) -> 0 | K25: =SUM(K23:K24) -> 0
C26: Sum finans | D26: =D22-D25 -> 0 | E26: =E22-E25 -> 0 | F26: =F22-F25 -> 0 | G26: =G22-G25 -> 0 | H26: =H22-H25 -> 0 | I26: =I22-I25 -> 0 | J26: =J22-J25 -> 0 | K26: =K22-K25 -> 0
C27: Resultat før skatt | D27: =D17+D26 -> 0 | E27: =E17+E26 -> 0 | F27: =F17+F26 -> 0 | G27: =G17+G26 -> 0 | H27: =H17+H26 -> 0 | I27: =I17+I26 -> 0 | J27: =J17+J26 -> 0 | K27: =K17+K26 -> 0
C29: Skatt og ekstraordinære poster
C30: Skattekostnad | D30: =D27*22% -> 0 | E30: =E27*23% -> 0 | F30: =F27*24% -> 0 | G30: =G27*25% -> 0 | H30: =H27*25% -> 0 | I30: =I27*26% -> 0 | J30: =J27*27% -> 0 | K30: =K27*28% -> 0
C31: Ordinært resultat | D31: =D27-D30 -> 0 | E31: =E27-E30 -> 0 | F31: =F27-F30 -> 0 | G31: =G27-G30 -> 0 | H31: =H27-H30 -> 0 | I31: =I27-I30 -> 0 | J31: =J27-J30 -> 0 | K31: =K27-K30 -> 0
C32: Ekstraordinære inntekter | D32: 0 | E32: 0 | F32: 0 | G32: 0 | H32: 0 | I32: 0 | J32: 0 | K32: 0
C33: Ekstraordinære kostnader | D33: 0 | E33: 0 | F33: 0 | G33: 0 | H33: 0 | I33: 0 | J33: 0 | K33: 0
C34: Skatt ekstraordinært | D34: 0 | E34: 0 | F34: 0 | G34: 0 | H34: 0 | I34: 0 | J34: 0 | K34: 0
C35: Årsresultat | D35: =D31+D32-D33-D34 -> 0 | E35: =E31+E32-E33-E34 -> 0 | F35: =F31+F32-F33-F34 -> 0 | G35: =G31+G32-G33-G34 -> 0 | H35: =H31+H32-H33-H34 -> 0 | I35: =I31+I32-I33-I34 -> 0 | J35: =J31+J32-J33-J34 -> 0 | K35: =K31+K32-K33-K34 -> 0
C37: Balanse i NOK tusen
C38: Eiendeler
C39: Goodwill | D39: 0 | E39: 0 | F39: 0 | G39: 0 | H39: 0 | I39: 0 | J39: 0 | K39: 0
C40: Immaterielle midler | D40: 0 | E40: 0 | F40: 0 | G40: 0 | H40: 0 | I40: 0 | J40: 0 | K40: 0
C41: Anleggsmidler
C42: Tomter, bygninger og annen fast eiendom
C43: Maskiner, anlegg og biler
C44: Driftsløsøre, inventar og verktøy
...

Sheet Nøkkeltall
B1: Finansielle nøkkeltall
B2: =Firmanavn -> 0
C4: Lønnsomhet | D4: =E4+1 -> 7 | E4: =F4+1 -> 6 | F4: =G4+1 -> 5 | G4: =H4+1 -> 4 | H4: =I4+1 -> 3 | I4: =J4+1 -> 2 | J4: =StartÅr+1 -> 1
C5: Driftsmargin | D5: =IFERROR(Regnskap!D17/Regnskap!D8,0) -> 0 | E5: =IFERROR(Regnskap!E17/Regnskap!E8,0) -> 0 | F5: =IFERROR(Regnskap!F17/Regnskap!F8,0) -> 0 | G5: =IFERROR(Regnskap!G17/Regnskap!G8,0) -> 0 | H5: =IFERROR(Regnskap!H17/Regnskap!H8,0) -> 0 | I5: =IFERROR(Regnskap!I17/Regnskap!I8,0) -> 0 | J5: =IFERROR(Regnskap!J17/Regnskap!J8,0) -> 0
C6: Kapitalens omløpshastighet | D6: =IFERROR(Regnskap!D8/((Regnskap!D60+Regnskap!E60)/2),0) -> 0 | E6: =IFERROR(Regnskap!E8/((Regnskap!E60+Regnskap!F60)/2),0) -> 0 | F6: =IFERROR(Regnskap!F8/((Regnskap!F60+Regnskap!G60)/2),0) -> 0 | G6: =IFERROR(Regnskap!G8/((Regnskap!G60+Regnskap!H60)/2),0) -> 0 | H6: =IFERROR(Regnskap!H8/((Regnskap!H60+Regnskap!I60)/2),0) -> 0 | I6: =IFERROR(Regnskap!I8/((Regnskap!I60+Regnskap!J60)/2),0) -> 0 | J6: =IFERROR(Regnskap!J8/((Regnskap!J60+Regnskap!K60)/2),0) -> 0
C7: Omløpshastighet kunder | D7: =IFERROR((Regnskap!D6*(1+Merverdiavgift))/((Regnskap!D54+Regnskap!E54)/2),0) -> 0 | E7: =IFERROR((Regnskap!E6*(1+Merverdiavgift))/((Regnskap!E54+Regnskap!F54)/2),0) -> 0 | F7: =IFERROR((Regnskap!F6*(1+Merverdiavgift))/((Regnskap!F54+Regnskap!G54)/2),0) -> 0 | G7: =IFERROR((Regnskap!G6*(1+Merverdiavgift))/((Regnskap!G54+Regnskap!H54)/2),0) -> 0 | H7: =IFERROR((Regnskap!H6*(1+Merverdiavgift))/((Regnskap!H54+Regnskap!I54)/2),0) -> 0 | I7: =IFERROR((Regnskap!I6*(1+Merverdiavgift))/((Regnskap!I54+Regnskap!J54)/2),0) -> 0 | J7: =IFERROR((Regnskap!J6*(1+Merverdiavgift))/((Regnskap!J54+Regnskap!K54)/2),0) -> 0
C8: Kredittiden til kundene | D8: =IFERROR(365/D7,0) -> 0 | E8: =IFERROR(365/E7,0) -> 0 | F8: =IFERROR(365/F7,0) -> 0 | G8: =IFERROR(365/G7,0) -> 0 | H8: =IFERROR(365/H7,0) -> 0 | I8: =IFERROR(365/I7,0) -> 0 | J8: =IFERROR(365/J7,0) -> 0
C9: Varekjøp | D9: =IFERROR(Regnskap!D10+Regnskap!D53-Regnskap!E53,0) -> 0 | E9: =IFERROR(Regnskap!E10+Regnskap!E53-Regnskap!F53,0) -> 0 | F9: =IFERROR(Regnskap!F10+Regnskap!F53-Regnskap!G53,0) -> 0 | G9: =IFERROR(Regnskap!G10+Regnskap!G53-Regnskap!H53,0) -> 0 | H9: =IFERROR(Regnskap!H10+Regnskap!H53-Regnskap!I53,0) -> 0 | I9: =IFERROR(Regnskap!I10+Regnskap!I53-Regnskap!J53,0) -> 0 | J9: =IFERROR(Regnskap!J10+Regnskap!J53-Regnskap!K53,0) -> 0
C10: Omløpshastighet leverandører | D10: =IFERROR(D9/((Regnskap!D77+Regnskap!E77)/2),0) -> 0 | E10: =IFERROR(E9/((Regnskap!E77+Regnskap!F77)/2),0) -> 0 | F10: =IFERROR(F9/((Regnskap!F77+Regnskap!G77)/2),0) -> 0 | G10: =IFERROR(G9/((Regnskap!G77+Regnskap!H77)/2),0) -> 0 | H10: =IFERROR(H9/((Regnskap!H77+Regnskap!I77)/2),0) -> 0 | I10: =IFERROR(I9/((Regnskap!I77+Regnskap!J77)/2),0) -> 0 | J10: =IFERROR(J9/((Regnskap!J77+Regnskap!K77)/2),0) -> 0
C11: Kredittiden til leverandører | D11: =IFERROR(365/D10,0) -> 0 | E11: =IFERROR(365/E10,0) -> 0 | F11: =IFERROR(365/F10,0) -> 0 | G11: =IFERROR(365/G10,0) -> 0 | H11: =IFERROR(365/H10,0) -> 0 | I11: =IFERROR(365/I10,0) -> 0 | J11: =IFERROR(365/J10,0) -> 0
C12: Omløpshastighet varer | D12: =IFERROR(Regnskap!D10/((Regnskap!D53+Regnskap!E53)/2),0) -> 0 | E12: =IFERROR(Regnskap!E10/((Regnskap!E53+Regnskap!F53)/2),0) -> 0 | F12: =IFERROR(Regnskap!F10/((Regnskap!F53+Regnskap!G53)/2),0) -> 0 | G12: =IFERROR(Regnskap!G10/((Regnskap!G53+Regnskap!H53)/2),0) -> 0 | H12: =IFERROR(Regnskap!H10/((Regnskap!H53+Regnskap!I53)/2),0) -> 0 | I12: =IFERROR(Regnskap!I10/((Regnskap!I53+Regnskap!J53)/2),0) -> 0 | J12: =IFERROR(Regnskap!J10/((Regnskap!J53+Regnskap!K53)/2),0) -> 0
C13: Lagringstid varer | D13: =IFERROR(365/D12,0) -> 0 | E13: =IFERROR(365/E12,0) -> 0 | F13: =IFERROR(365/F12,0) -> 0 | G13: =IFERROR(365/G12,0) -> 0 | H13: =IFERROR(365/H12,0) -> 0 | I13: =IFERROR(365/I12,0) -> 0 | J13: =IFERROR(365/J12,0) -> 0
C14: Resultatgrad | D14: =IFERROR((Regnskap!D27+Regnskap!D25)/Regnskap!D8,0) -> 0 | E14: =IFERROR((Regnskap!E27+Regnskap!E25)/Regnskap!E8,0) -> 0 | F14: =IFERROR((Regnskap!F27+Regnskap!F25)/Regnskap!F8,0) -> 0 | G14: =IFERROR((Regnskap!G27+Regnskap!G25)/Regnskap!G8,0) -> 0 | H14: =IFERROR((Regnskap!H27+Regnskap!H25)/Regnskap!H8,0) -> 0 | I14: =IFERROR((Regnskap!I27+Regnskap!I25)/Regnskap!I8,0) -> 0 | J14: =IFERROR((Regnskap!J27+Regnskap!J25)/Regnskap!J8,0) -> 0
C15: Totalkapitalrentabilitet | D15: =IFERROR(D14*D6,0) -> 0 | E15: =IFERROR(E14*E6,0) -> 0 | F15: =IFERROR(F14*F6,0) -> 0 | G15: =IFERROR(G14*G6,0) -> 0 | H15: =IFERROR(H14*H6,0) -> 0 | I15: =IFERROR(I14*I6,0) -> 0 | J15: =IFERROR(J14*J6,0) -> 0
C16: Gjennomsnittlig gjeldsrente | D16: =IFERROR(Regnskap!D23/((Regnskap!D83+Regnskap!E83)/2),0) -> 0 | E16: =IFERROR(Regnskap!E23/((Regnskap!E83+Regnskap!F83)/2),0) -> 0 | F16: =IFERROR(Regnskap!F23/((Regnskap!F83+Regnskap!G83)/2),0) -> 0 | G16: =IFERROR(Regnskap!G23/((Regnskap!G83+Regnskap!H83)/2),0) -> 0 | H16: =IFERROR(Regnskap!H23/((Regnskap!H83+Regnskap!I83)/2),0) -> 0 | I16: =IFERROR(Regnskap!I23/((Regnskap!I83+Regnskap!J83)/2),0) -> 0 | J16: =IFERROR(Regnskap!J23/((Regnskap!J83+Regnskap!K83)/2),0) -> 0
C17: Egenkapitalrentabiliteten | D17: =IFERROR(Regnskap!D27/((Regnskap!D67+Regnskap!E67)/2),0) -> 0 | E17: =IFERROR(Regnskap!E27/((Regnskap!E67+Regnskap!F67)/2),0) -> 0 | F17: =IFERROR(Regnskap!F27/((Regnskap!F67+Regnskap!G67)/2),0) -> 0 | G17: =IFERROR(Regnskap!G27/((Regnskap!G67+Regnskap!H67)/2),0) -> 0 | H17: =IFERROR(Regnskap!H27/((Regnskap!H67+Regnskap!I67)/2),0) -> 0 | I17: =IFERROR(Regnskap!I27/((Regnskap!I67+Regnskap!J67)/2),0) -> 0 | J17: =IFERROR(Regnskap!J27/((Regnskap!J67+Regnskap!K67)/2),0) -> 0
C18: Brekkstangformelen | D18: =IFERROR(D15+(D15-D16)*D29,0) -> 0 | E18: =IFERROR(E15+(E15-E16)*E29,0) -> 0 | F18: =IFERROR(F15+(F15-F16)*F29,0) -> 0 | G18: =IFERROR(G15+(G15-G16)*G29,0) -> 0 | H18: =IFERROR(H15+(H15-H16)*H29,0) -> 0 | I18: =IFERROR(I15+(I15-I16)*I29,0) -> 0 | J18: =IFERROR(J15+(J15-J16)*J29,0) -> 0
C20: Likviditet | D20: =D4 -> 7 | E20: =E4 -> 6 | F20: =F4 -> 5 | G20: =G4 -> 4 | H20: =H4 -> 3 | I20: =I4 -> 2 | J20: =J4 -> 1
C21: Likviditetsgrad 1 | D21: =IFERROR(Regnskap!D59/Regnskap!D82,0) -> 0 | E21: =IFERROR(Regnskap!E59/Regnskap!E82,0) -> 0 | F21: =IFERROR(Regnskap!F59/Regnskap!F82,0) -> 0 | G21: =IFERROR(Regnskap!G59/Regnskap!G82,0) -> 0 | H21: =IFERROR(Regnskap!H59/Regnskap!H82,0) -> 0 | I21: =IFERROR(Regnskap!I59/Regnskap!I82,0) -> 0 | J21: =IFERROR(Regnskap!J59/Regnskap!J82,0) -> 0 | K21: =Regnskap!K59/Regnskap!K82 -> #DIV/0!
C22: Likviditetsgrad 2 | D22: =IFERROR((Regnskap!D59-Regnskap!D53)/Regnskap!D82,0) -> 0 | E22: =IFERROR((Regnskap!E59-Regnskap!E53)/Regnskap!E82,0) -> 0 | F22: =IFERROR((Regnskap!F59-Regnskap!F53)/Regnskap!F82,0) -> 0 | G22: =IFERROR((Regnskap!G59-Regnskap!G53)/Regnskap!G82,0) -> 0 | H22: =IFERROR((Regnskap!H59-Regnskap!H53)/Regnskap!H82,0) -> 0 | I22: =IFERROR((Regnskap!I59-Regnskap!I53)/Regnskap!I82,0) -> 0 | J22: =IFERROR((Regnskap!J59-Regnskap!J53)/Regnskap!J82,0) -> 0 | K22: =(Regnskap!K59-Regnskap!K53)/Regnskap!K82 -> #DIV/0!
C23: Arbeidskapital (i tusen NOK) | D23: =Regnskap!D59-Regnskap!D82 -> 0 | E23: =Regnskap!E59-Regnskap!E82 -> 0 | F23: =Regnskap!F59-Regnskap!F82 -> 0 | G23: =Regnskap!G59-Regnskap!G82 -> 0 | H23: =Regnskap!H59-Regnskap!H82 -> 0 | I23: =Regnskap!I59-Regnskap!I82 -> 0 | J23: =Regnskap!J59-Regnskap!J82 -> 0 | K23: =Regnskap!K59-Regnskap!K82 -> 0
C24: Arbeidskapitalen/Driftsinntekter | D24: =IFERROR(D23/Regnskap!D8,0) -> 0 | E24: =IFERROR(E23/Regnskap!E8,0) -> 0 | F24: =IFERROR(F23/Regnskap!F8,0) -> 0 | G24: =IFERROR(G23/Regnskap!G8,0) -> 0 | H24: =IFERROR(H23/Regnskap!H8,0) -> 0 | I24: =IFERROR(I23/Regnskap!I8,0) -> 0 | J24: =IFERROR(J23/Regnskap!J8,0) -> 0 | K24: =K23/Regnskap!K8 -> #DIV/0!
C25: EBITDA | D25: =Regnskap!D17+Regnskap!D14+Regnskap!D13 -> 0 | E25: =Regnskap!E17+Regnskap!E14+Regnskap!E13 -> 0 | F25: =Regnskap!F17+Regnskap!F14+Regnskap!F13 -> 0 | G25: =Regnskap!G17+Regnskap!G14+Regnskap!G13 -> 0 | H25: =Regnskap!H17+Regnskap!H14+Regnskap!H13 -> 0 | I25: =Regnskap!I17+Regnskap!I14+Regnskap!I13 -> 0 | J25: =Regnskap!J17+Regnskap!J14+Regnskap!J13 -> 0 | K25: =Regnskap!K17+Regnskap!K14+Regnskap!K13 -> 0
C26: EBITDA/Driftsinntekter | D26: =IFERROR(D25/Regnskap!D8,0) -> 0 | E26: =IFERROR(E25/Regnskap!E8,0) -> 0 | F26: =IFERROR(F25/Regnskap!F8,0) -> 0 | G26: =IFERROR(G25/Regnskap!G8,0) -> 0 | H26: =IFERROR(H25/Regnskap!H8,0) -> 0 | I26: =IFERROR(I25/Regnskap!I8,0) -> 0 | J26: =IFERROR(J25/Regnskap!J8,0) -> 0 | K26: =K25/Regnskap!K8 -> #DIV/0!
C28: Soliditet | D28: =D4 -> 7 | E28: =E4 -> 6 | F28: =F4 -> 5 | G28: =G4 -> 4 | H28: =H4 -> 3 | I28: =I4 -> 2 | J28: =J4 -> 1
C29: Gjeldsgrad | D29: =IFERROR(((Regnskap!D83+Regnskap!E83)/2)/((Regnskap!D67+Regnskap!E67)/2),0) -> 0 | E29: =IFERROR(((Regnskap!E83+Regnskap!F83)/2)/((Regnskap!E67+Regnskap!F67)/2),0) -> 0 | F29: =IFERROR(((Regnskap!F83+Regnskap!G83)/2)/((Regnskap!F67+Regnskap!G67)/2),0) -> 0 | G29: =IFERROR(((Regnskap!G83+Regnskap!H83)/2)/((Regnskap!G67+Regnskap!H67)/2),0) -> 0 | H29: =IFERROR(((Regnskap!H83+Regnskap!I83)/2)/((Regnskap!H67+Regnskap!I67)/2),0) -> 0 | I29: =IFERROR(((Regnskap!I83+Regnskap!J83)/2)/((Regnskap!I67+Regnskap!J67)/2),0) -> 0 | J29: =IFERROR(((Regnskap!J83+Regnskap!K83)/2)/((Regnskap!J67+Regnskap!K67)/2),0) -> 0
C30: Egenkapitalandel | D30: =IFERROR(Regnskap!D67/Regnskap!D85,0) -> 0 | E30: =IFERROR(Regnskap!E67/Regnskap!E85,0) -> 0 | F30: =IFERROR(Regnskap!F67/Regnskap!F85,0) -> 0 | G30: =IFERROR(Regnskap!G67/Regnskap!G85,0) -> 0 | H30: =IFERROR(Regnskap!H67/Regnskap!H85,0) -> 0 | I30: =IFERROR(Regnskap!I67/Regnskap!I85,0) -> 0 | J30: =IFERROR(Regnskap!J67/Regnskap!J85,0) -> 0
C31: Langsiktig anleggsfinansiering | D31: =IFERROR(Regnskap!D51/(Regnskap!D67+Regnskap!D75),0) -> 0 | E31: =IFERROR(Regnskap!E51/(Regnskap!E67+Regnskap!E75),0) -> 0 | F31: =IFERROR(Regnskap!F51/(Regnskap!F67+Regnskap!F75),0) -> 0 | G31: =IFERROR(Regnskap!G51/(Regnskap!G67+Regnskap!G75),0) -> 0 | H31: =IFERROR(Regnskap!H51/(Regnskap!H67+Regnskap!H75),0) -> 0 | I31: =IFERROR(Regnskap!I51/(Regnskap!I67+Regnskap!I75),0) -> 0 | J31: =IFERROR(Regnskap!J51/(Regnskap!J67+Regnskap!J75),0) -> 0

Sheet Grafer
B1: Grafer
B2: =Firmanavn -> 0
B4: Lønnsomhet
B31: Likviditet | O31: Soliditet
C67: =Nøkkeltall!D4 -> 7 | D67: =Nøkkeltall!E4 -> 6 | E67: =Nøkkeltall!F4 -> 5 | F67: =Nøkkeltall!G4 -> 4 | G67: =Nøkkeltall!H4 -> 3 | H67: =Nøkkeltall!I4 -> 2 | I67: =Nøkkeltall!J4 -> 1
B69: LØNNSOMHET
B70: ProsentVerdier | K70: Tider | T70: Grader
B71: 1 | K71: 1 | T71: 1
B72: År | K72: År | T72: År
B73: =INDEX(B74:B79,$B$71,1) -> Driftsmargin | C73: =INDEX(C74:C79,$B$71,1) -> 0 | D73: =INDEX(D74:D79,$B$71,1) -> 0 | E73: =INDEX(E74:E79,$B$71,1) -> 0 | F73: =INDEX(F74:F79,$B$71,1) -> 0 | G73: =INDEX(G74:G79,$B$71,1) -> 0 | H73: =INDEX(H74:H79,$B$71,1) -> 0 | I73: =INDEX(I74:I79,$B$71,1) -> 0 | K73: =INDEX(K74:K81,$K$71,1) -> Kapitalens omløpshastighet | L73: =INDEX(L74:L81,$K$71,1) -> 0 | M73: =INDEX(M74:M81,$K$71,1) -> 0 | N73: =INDEX(N74:N81,$K$71,1) -> 0 | O73: =INDEX(O74:O81,$K$71,1) -> 0 | P73: =INDEX(P74:P81,$K$71,1) -> 0 | Q73: =INDEX(Q74:Q81,$K$71,1) -> 0 | R73: =INDEX(R74:R81,$K$71,1) -> 0 | T73: =INDEX(T74:T75,$T$71,1) -> Resultatgrad | U73: =INDEX(U74:U75,$T$71,1) -> 0 | V73: =INDEX(V74:V75,$T$71,1) -> 0 | W73: =INDEX(W74:W75,$T$71,1) -> 0 | X73: =INDEX(X74:X75,$T$71,1) -> 0 | Y73: =INDEX(Y74:Y75,$T$71,1) -> 0 | Z73: =INDEX(Z74:Z75,$T$71,1) -> 0 | AA73: =INDEX(AA74:AA75,$T$71,1) -> 0
B74: =Nøkkeltall!$C$5 -> Driftsmargin | C74: =Nøkkeltall!$D$5 -> 0 | D74: =Nøkkeltall!$E$5 -> 0 | E74: =Nøkkeltall!$F$5 -> 0 | F74: =Nøkkeltall!$G$5 -> 0 | G74: =Nøkkeltall!$H$5 -> 0 | H74: =Nøkkeltall!$I$5 -> 0 | I74: =Nøkkeltall!$J$5 -> 0 | K74: =Nøkkeltall!$C$6 -> Kapitalens omløpshastighet | L74: =Nøkkeltall!$D$6 -> 0 | M74: =Nøkkeltall!$E$6 -> 0 | N74: =Nøkkeltall!$F$6 -> 0 | O74: =Nøkkeltall!$G$6 -> 0 | P74: =Nøkkeltall!$H$6 -> 0 | Q74: =Nøkkeltall!$I$6 -> 0 | R74: =Nøkkeltall!$J$6 -> 0 | T74: =Nøkkeltall!$C$14 -> Resultatgrad | U74: =Nøkkeltall!$D$14 -> 0 | V74: =Nøkkeltall!$E$14 -> 0 | W74: =Nøkkeltall!$F$14 -> 0 | X74: =Nøkkeltall!$G$14 -> 0 | Y74: =Nøkkeltall!$H$14 -> 0 | Z74: =Nøkkeltall!$I$14 -> 0 | AA74: =Nøkkeltall!$J$14 -> 0
B75: =Nøkkeltall!$C$15 -> Totalkapitalrentabilitet | C75: =Nøkkeltall!$D$15 -> 0 | D75: =Nøkkeltall!$E$15 -> 0 | E75: =Nøkkeltall!$F$15 -> 0 | F75: =Nøkkeltall!$G$15 -> 0 | G75: =Nøkkeltall!$H$15 -> 0 | H75: =Nøkkeltall!$I$15 -> 0 | I75: =Nøkkeltall!$J$15 -> 0 | K75: =Nøkkeltall!$C$7 -> Omløpshastighet kunder | L75: =Nøkkeltall!$D$7 -> 0 | M75: =Nøkkeltall!$E$7 -> 0 | N75: =Nøkkeltall!$F$7 -> 0 | O75: =Nøkkeltall!$G$7 -> 0 | P75: =Nøkkeltall!$H$7 -> 0 | Q75: =Nøkkeltall!$I$7 -> 0 | R75: =Nøkkeltall!$J$7 -> 0
B76: =Nøkkeltall!$C$16 -> Gjennomsnittlig gjeldsrente | C76: =Nøkkeltall!$D$16 -> 0 | D76: =Nøkkeltall!$E$16 -> 0 | E76: =Nøkkeltall!$F$16 -> 0 | F76: =Nøkkeltall!$G$16 -> 0 | G76: =Nøkkeltall!$H$16 -> 0 | H76: =Nøkkeltall!$I$16 -> 0 | I76: =Nøkkeltall!$J$16 -> 0 | K76: =Nøkkeltall!$C$8 -> Kredittiden til kundene | L76: =Nøkkeltall!$D$8 -> 0 | M76: =Nøkkeltall!$E$8 -> 0 | N76: =Nøkkeltall!$F$8 -> 0 | O76: =Nøkkeltall!$G$8 -> 0 | P76: =Nøkkeltall!$H$8 -> 0 | Q76: =Nøkkeltall!$I$8 -> 0 | R76: =Nøkkeltall!$J$8 -> 0
B77: =Nøkkeltall!$C$17 -> Egenkapitalrentabiliteten | C77: =Nøkkeltall!$D$17 -> 0 | D77: =Nøkkeltall!$E$17 -> 0 | E77: =Nøkkeltall!$F$17 -> 0 | F77: =Nøkkeltall!$G$17 -> 0 | G77: =Nøkkeltall!$H$17 -> 0 | H77: =Nøkkeltall!$I$17 -> 0 | I77: =Nøkkeltall!$J$17 -> 0 | K77: =Nøkkeltall!$C$10 -> Omløpshastighet leverandører | L77: =Nøkkeltall!$D$10 -> 0 | M77: =Nøkkeltall!$E$10 -> 0 | N77: =Nøkkeltall!$F$10 -> 0 | O77: =Nøkkeltall!$G$10 -> 0 | P77: =Nøkkeltall!$H$10 -> 0 | Q77: =Nøkkeltall!$I$10 -> 0 | R77: =Nøkkeltall!$J$10 -> 0
B78: =Nøkkeltall!$C$18 -> Brekkstangformelen | C78: =Nøkkeltall!$D$18 -> 0 | D78: =Nøkkeltall!$E$18 -> 0 | E78: =Nøkkeltall!$F$18 -> 0 | F78: =Nøkkeltall!$G$18 -> 0 | G78: =Nøkkeltall!$H$18 -> 0 | H78: =Nøkkeltall!$I$18 -> 0 | I78: =Nøkkeltall!$J$18 -> 0 | K78: =Nøkkeltall!$C$11 -> Kredittiden til leverandører | L78: =Nøkkeltall!$D$11 -> 0 | M78: =Nøkkeltall!$E$11 -> 0 | N78: =Nøkkeltall!$F$11 -> 0 | O78: =Nøkkeltall!$G$11 -> 0 | P78: =Nøkkeltall!$H$11 -> 0 | Q78: =Nøkkeltall!$I$11 -> 0 | R78: =Nøkkeltall!$J$11 -> 0
K79: =Nøkkeltall!$C$12 -> Omløpshastighet varer | L79: =Nøkkeltall!$D$12 -> 0 | M79: =Nøkkeltall!$E$12 -> 0 | N79: =Nøkkeltall!$F$12 -> 0 | O79: =Nøkkeltall!$G$12 -> 0 | P79: =Nøkkeltall!$H$12 -> 0 | Q79: =Nøkkeltall!$I$12 -> 0 | R79: =Nøkkeltall!$J$12 -> 0
K80: =Nøkkeltall!$C$13 -> Lagringstid varer | L80: =Nøkkeltall!$D$13 -> 0 | M80: =Nøkkeltall!$E$13 -> 0 | N80: =Nøkkeltall!$F$13 -> 0 | O80: =Nøkkeltall!$G$13 -> 0 | P80: =Nøkkeltall!$H$13 -> 0 | Q80: =Nøkkeltall!$I$13 -> 0 | R80: =Nøkkeltall!$J$13 -> 0
B83: Grader | K83: Beløp | T83: Grader
B84: 2 | K84: 2 | T84: 3
B85: År | K85: År | T85: År
B86: =INDEX(B87:B91,$B$84,1) -> Likviditetsgrad 2 | C86: =INDEX(C87:C91,$B$84,1) -> 0 | D86: =INDEX(D87:D91,$B$84,1) -> 0 | E86: =INDEX(E87:E91,$B$84,1) -> 0 | F86: =INDEX(F87:F91,$B$84,1) -> 0 | G86: =INDEX(G87:G91,$B$84,1) -> 0 | H86: =INDEX(H87:H91,$B$84,1) -> 0 | I86: =INDEX(I87:I91,$B$84,1) -> 0 | K86: =INDEX(K87:K89,$K$84,1) -> EBITDA | L86: =INDEX(L87:L89,$K$84,1) -> 0 | M86: =INDEX(M87:M89,$K$84,1) -> 0 | N86: =INDEX(N87:N89,$K$84,1) -> 0 | O86: =INDEX(O87:O89,$K$84,1) -> 0 | P86: =INDEX(P87:P89,$K$84,1) -> 0 | Q86: =INDEX(Q87:Q89,$K$84,1) -> 0 | R86: =INDEX(R87:R89,$K$84,1) -> 0 | T86: =INDEX(T87:T90,$T$84,1) -> Langsiktig anleggsfinansiering | U86: =INDEX(U87:U90,$T$84,1) -> 0 | V86: =INDEX(V87:V90,$T$84,1) -> 0 | W86: =INDEX(W87:W90,$T$84,1) -> 0 | X86: =INDEX(X87:X90,$T$84,1) -> 0 | Y86: =INDEX(Y87:Y90,$T$84,1) -> 0 | Z86: =INDEX(Z87:Z90,$T$84,1) -> 0 | AA86: =INDEX(AA87:AA90,$T$84,1) -> 0
B87: =Nøkkeltall!$C$21 -> Likviditetsgrad 1 | C87: =Nøkkeltall!$D$21 -> 0 | D87: =Nøkkeltall!$E$21 -> 0 | E87: =Nøkkeltall!$F$21 -> 0 | F87: =Nøkkeltall!$G$21 -> 0 | G87: =Nøkkeltall!$H$21 -> 0 | H87: =Nøkkeltall!$I$21 -> 0 | I87: =Nøkkeltall!$J$21 -> 0 | K87: =Nøkkeltall!$C$23 -> Arbeidskapital (i tusen NOK) | L87: =Nøkkeltall!$D$23 -> 0 | M87: =Nøkkeltall!$E$23 -> 0 | N87: =Nøkkeltall!$F$23 -> 0 | O87: =Nøkkeltall!$G$23 -> 0 | P87: =Nøkkeltall!$H$23 -> 0 | Q87: =Nøkkeltall!$I$23 -> 0 | R87: =Nøkkeltall!$J$23 -> 0 | T87: =Nøkkeltall!$C$29 -> Gjeldsgrad | U87: =Nøkkeltall!$D$29 -> 0 | V87: =Nøkkeltall!$E$29 -> 0 | W87: =Nøkkeltall!$F$29 -> 0 | X87: =Nøkkeltall!$G$29 -> 0 | Y87: =Nøkkeltall!$H$29 -> 0 | Z87: =Nøkkeltall!$I$29 -> 0 | AA87: =Nøkkeltall!$J$29 -> 0
B88: =Nøkkeltall!$C$22 -> Likviditetsgrad 2 | C88: =Nøkkeltall!$D$22 -> 0 | D88: =Nøkkeltall!$E$22 -> 0 | E88: =Nøkkeltall!$F$22 -> 0 | F88: =Nøkkeltall!$G$22 -> 0 | G88: =Nøkkeltall!$H$22 -> 0 | H88: =Nøkkeltall!$I$22 -> 0 | I88: =Nøkkeltall!$J$22 -> 0 | K88: =Nøkkeltall!$C$25 -> EBITDA | L88: =Nøkkeltall!$D$25 -> 0 | M88: =Nøkkeltall!$E$25 -> 0 | N88: =Nøkkeltall!$F$25 -> 0 | O88: =Nøkkeltall!$G$25 -> 0 | P88: =Nøkkeltall!$H$25 -> 0 | Q88: =Nøkkeltall!$I$25 -> 0 | R88: =Nøkkeltall!$J$25 -> 0 | T88: =Nøkkeltall!$C$30 -> Egenkapitalandel | U88: =Nøkkeltall!$D$30 -> 0 | V88: =Nøkkeltall!$E$30 -> 0 | W88: =Nøkkeltall!$F$30 -> 0 | X88: =Nøkkeltall!$G$30 -> 0 | Y88: =Nøkkeltall!$H$30 -> 0 | Z88: =Nøkkeltall!$I$30 -> 0 | AA88: =Nøkkeltall!$J$30 -> 0
B89: =Nøkkeltall!$C$24 -> Arbeidskapitalen/Driftsinntekter | C89: =Nøkkeltall!$D$24 -> 0 | D89: =Nøkkeltall!$E$24 -> 0 | E89: =Nøkkeltall!$F$24 -> 0 | F89: =Nøkkeltall!$G$24 -> 0 | G89: =Nøkkeltall!$H$24 -> 0 | H89: =Nøkkeltall!$I$24 -> 0 | I89: =Nøkkeltall!$J$24 -> 0 | T89: =Nøkkeltall!$C$31 -> Langsiktig anleggsfinansiering | U89: =Nøkkeltall!$D$31 -> 0 | V89: =Nøkkeltall!$E$31 -> 0 | W89: =Nøkkeltall!$F$31 -> 0 | X89: =Nøkkeltall!$G$31 -> 0 | Y89: =Nøkkeltall!$H$31 -> 0 | Z89: =Nøkkeltall!$I$31 -> 0 | AA89: =Nøkkeltall!$J$31 -> 0
B90: =Nøkkeltall!$C$26 -> EBITDA/Driftsinntekter | C90: =Nøkkeltall!$D$26 -> 0 | D90: =Nøkkeltall!$E$26 -> 0 | E90: =Nøkkeltall!$F$26 -> 0 | F90: =Nøkkeltall!$G$26 -> 0 | G90: =Nøkkeltall!$H$26 -> 0 | H90: =Nøkkeltall!$I$26 -> 0 | I90: =Nøkkeltall!$J$26 -> 0
